Workbook

Sheet T1.2026
A1: CÔNG TY CỔ PHẦN GẠCH MEN PHƯƠNG NAM
A2: PHÂN XƯỞNG SẢN XUẤT DC2
A4: BÁO CÁO KẾT QUẢ SẢN XUẤT DÂY CHUYỀN SỐ 2 THÁNG 01 NĂM 2026
A6: I. Kết quả sản xuất tháng 01 năm 2026:
A7: I. Kết quả sản lượng – Chất lượng – Thu hồi ∑AB/ép :
A8: 1. Kết quả thực hiện Sản lượng – Chất lượng – Thu hồi ∑AB/ép
A9: Kích thước | C9: Sản Lượng Ép | D9: Sản lượng thu hồi | G9: Tổng (A1+A+B) | H9: Số ngày sx | I9: TB/ngày | J9: A/ép (%) | K9: C | L9: Hủy | M9: Dừng ép
A10: KH/TH | B10: ĐVT | D10: A1 | E10: A | F10: B | I10: m2 | K10: C/ép | L10: Hủy/ép | M10: phút/ngày
A11: KẾ HOẠCH 40*80 | B11: m2 | C11: =+(G11*100)/98 -> 229821.43 | D11: =+D12*$G$11/100 -> 202702.5 | E11: =+E12*$G$11/100 -> 15765.75 | F11: =+F12*$G$11/100 -> 6756.75 | G11: =+H11*I11 -> 225225 | H11: 15 | I11: 15015
B12: % | D12: 90 | E12: 7 | F12: 3 | G12: 100 | J12: 98 | K12: =100-J12 -> 2 | M12: 40
A13: THỰC HIỆN 40*80 | B13: m2 | C13: 220975 | D13: 209372.8 | E13: 0 | F13: 10566.4 | G13: =+SUM(D13:F13) -> 219939.2 | H13: 15 | I13: =+G13/H13 -> 14662.613 | K13: 704 | L13: 962.6
B14: % | D14: =+D13/G13*100 -> 95.195763 | E14: =+E13/G13*100 -> 0 | F14: =+F13/G13*100 -> 4.8042368 | G14: =SUM(D14:F14) -> 100 | J14: =+G13/C13*100 -> 99.531259 | K14: =100-J14 -> 0.46874081 | M14: 45.533333
A15: So sánh TH/KH 40*80 | B15: m2 | C15: =+C13-C11 -> -8846.4286 | D15: =+D13-D11 -> 6670.3 | E15: =+(E13-E11) -> -15765.75 | F15: =+F13-F11 -> 3809.65 | G15: =SUM(D15:F15) -> -5285.8
B16: % | D16: =+D14-D12 -> 5.1957632 | E16: =+E14-E12 -> -7 | F16: =+F14-F12 -> 1.8042368 | G16: 0 | N16: =97.5+1.29 -> 98.79
A17: KẾ HOẠCH 40*80 | B17: m2 | C17: =+(G17*100)/98 -> 0 | D17: =+D18*$G$17/100 -> 0 | E17: =+E18*$G$17/100 -> 0 | F17: =+F18*$G$17/100 -> 0 | G17: =+H17*I17 -> 0 | M17: 40
B18: % | D18: 89 | E18: 8 | F18: 3 | G18: =SUM(D18:F18) -> 100 | J18: 98 | K18: =100-J18 -> 2
A19: THỰC HIỆN 40*80 | B19: m2 | G19: =SUM(D19:F19) -> 0 | I19: =+G19/H19 -> #DIV/0!
B20: % | D20: =+D19/G19*100 -> #DIV/0! | E20: =+E19/G19*100 -> #DIV/0! | F20: =+F19/G19*100 -> #DIV/0! | G20: =SUM(D20:F20) -> #DIV/0! | J20: =+G19/C19*100 -> #DIV/0! | K20: =100-J20 -> #DIV/0!
A21: So sánh TH/KH 40*80 | B21: m2 | C21: =+C19-C17 -> 0 | D21: =+D19-D17 -> 0 | E21: =+(E19-E17) -> 0 | F21: =+F19-F17 -> 0 | G21: =SUM(D21:F21) -> 0
B22: % | D22: =+D20-D18 -> #DIV/0! | E22: =+(E20-E18) -> #DIV/0! | F22: =+F20-F18 -> #DIV/0! | G22: 0
A23: TỔNG KẾ HOẠCH | B23: m2 | C23: =+C11+C17 -> 229821.43 | D23: =+D11+D17 -> 202702.5 | E23: =+E11+E17 -> 15765.75 | F23: =+F11+F17 -> 6756.75 | G23: =SUM(D23:F23) -> 225225 | H23: =+H11+H17 -> 15 | I23: =+G23/H23 -> 15015
B24: % | D24: =+D23/G23*100 -> 90 | E24: =+E23/G23*100 -> 7 | F24: =+F23/G23*100 -> 3 | G24: =SUM(D24:F24) -> 100 | J24: =+G23/C23*100 -> 98 | K24: =100-J24 -> 2
A25: TỔNG THỰC HIỆN | B25: m2 | C25: =+C13+C19 -> 220975 | D25: =+D13+D19 -> 209372.8 | E25: =+E13+E19 -> 0 | F25: =+F13+F19 -> 10566.4 | G25: =SUM(D25:F25) -> 219939.2 | H25: =+H13+H19 -> 15 | I25: =+G25/H25 -> 14662.613
B26: % | D26: =+D25/G25*100 -> 95.195763 | E26: =+E25/G25*100 -> 0 | F26: =+F25/G25*100 -> 4.8042368 | G26: =SUM(D26:F26) -> 100 | J26: =+G25/C25*100 -> 99.531259 | K26: =100-J26 -> 0.46874081
A27: 2. Kết quả thực hiện các thương hiệu trong tháng 01/2026
A28: 1. Kết quả thực hiện các thương hiệu :
A29: ➢ SX 60x60 men matt
A30: Kh/TH | B30: Thực Hiện | J30: Tỷ lệ % | L30: Ghi chú
B31: A1 | D31: A | F31: B | H31: Tổng A1+A+B
A32: Luxury | H32: =+B32+D32+F32 -> 0
B33: =+B32/$H$32*100 -> #DIV/0! | C33: =+C32/C44*100 -> #REF! | D33: =+D32/$H$32*100 -> #DIV/0! | E33: =+E32/E44*100 -> #REF! | F33: =+F32/$H$32*100 -> #DIV/0! | G33: =+G32/G44*100 -> #REF! | H33: =+H32/$H$32*100 -> #DIV/0! | I33: =+I32/I44*100 -> #REF! | J33: =+H32/$H$44*100 -> #DIV/0!
A34: Green Home | H34: =+B34+D34+F34 -> 0
B35: =+B34/$H$34*100 -> #DIV/0! | C35: =+C34/C44*100 -> #REF! | D35: =+D34/$H$34*100 -> #DIV/0! | E35: =+E34/E44*100 -> #REF! | F35: =+F34/$H$34*100 -> #DIV/0! | G35: =+G34/G44*100 -> #REF! | H35: =+H34/$H$34*100 -> #DIV/0! | I35: =+I34/I44*100 -> #REF! | J35: =+H34/$H$44*100 -> #DIV/0!
A36: Crown | H36: =+B36+D36+F36 -> 0
B37: =+B36/$H$36*100 -> #DIV/0! | D37: =+D36/$H$36*100 -> #DIV/0! | F37: =+F36/$H$36*100 -> #DIV/0! | H37: =+H36/$H$36*100 -> #DIV/0! | J37: =+H36/$H$44*100 -> #DIV/0!
A38: Havira | H38: =+B38+D38+F38 -> 0
B39: =+B38/$H$38*100 -> #DIV/0! | C39: =+C38/C44*100 -> #REF! | D39: =+D38/$H$38*100 -> #DIV/0! | E39: =+E38/E44*100 -> #REF! | F39: =+F38/$H$38*100 -> #DIV/0! | G39: =+G38/G44*100 -> #REF! | H39: =+H38/$H$38*100 -> #DIV/0! | I39: =+I38/I44*100 -> #REF! | J39: =+H38/$H$44*100 -> #DIV/0!
A40: Xanh Tím | H40: =+B40+D40+F40 -> 0
B41: =+B40/$H$40*100 -> #DIV/0! | C41: =+C40/C44*100 -> #REF! | D41: =+D40/$H$40*100 -> #DIV/0! | E41: =+E40/E44*100 -> #REF! | F41: =+F40/$H$40*100 -> #DIV/0! | G41: =+G40/G44*100 -> #REF! | H41: =+H40/$H$40*100 -> #DIV/0! | I41: =+I40/I44*100 -> #REF! | J41: =+H40/$H$44*100 -> #DIV/0!
H42: =+B42+D42+F42 -> 0
...

Sheet T3.2026
A1: CÔNG TY CỔ PHẦN GẠCH MEN PHƯƠNG NAM
A2: PHÂN XƯỞNG SẢN XUẤT DC2
A4: BÁO CÁO KẾT QUẢ SẢN XUẤT DÂY CHUYỀN SỐ 2 THÁNG 3 NĂM 2026
A6: I. Kết quả sản xuất tháng 03 năm 2026:
A7: I. Kết quả sản lượng – Chất lượng – Thu hồi ∑AB/ép :
A8: 1. Kết quả thực hiện Sản lượng – Chất lượng – Thu hồi ∑AB/ép
A9: Kích thước | C9: Sản Lượng Ép | D9: Sản lượng thu hồi | G9: Tổng (A1+A+B) | H9: Số ngày sx | I9: TB/ngày | J9: A/ép (%) | K9: C | L9: Hủy | M9: Dừng ép
A10: KH/TH | B10: ĐVT | D10: A1 | E10: A | F10: B | I10: m2 | K10: C/ép | L10: Hủy/ép | M10: phút/ngày
A11: KẾ HOẠCH 50*50 | B11: m2 | C11: 379901 | D11: 349965 | E11: 11169 | F11: 11169 | G11: =SUM(D11:F11) -> 372303 | H11: 28 | I11: 13789 | K11: 7589
B12: % | D12: 94 | E12: 3 | F12: 3 | G12: 100 | J12: 98 | K12: 2 | M12: 100 | P12: 5.3
A13: THỰC HIỆN 50*50 | B13: m2 | C13: =+'[1]31.3'!$F$21:$F$21 -> 421167 | D13: =+'[1]31.3'!$I$21 -> 413131.5 | E13: 0 | F13: =+'[1]31.3'!$K$21 -> 2607 | G13: =SUM(D13:F13) -> 415738.5 | H13: 28 | I13: 13586 | K13: 1170 | L13: 1053 | P13: =16-P12 -> 10.7
B14: % | D14: =+D13/G13*100 -> 99.372923 | E14: =+E13/G13*100 -> 0 | F14: =+F13/G13*100 -> 0.62707688 | G14: =SUM(D14:F14) -> 100 | J14: =+G13/C13*100 -> 98.711081 | K14: =100-J14 -> 1.2889186 | M14: 83
A15: So sánh TH/KH 50*50 | B15: m2 | C15: =+C13-C11 -> 41266 | D15: =+D13-D11 -> 63166.5 | E15: =+(E13-E11) -> -11169 | F15: =+F13-F11 -> -8562 | G15: =SUM(D15:F15) -> 43435.5
B16: % | D16: =+D14-D12 -> 5.3729231 | E16: =+E14-E12 -> -3 | F16: =+F14-F12 -> -2.3729231 | G16: 0 | N16: =97.5+1.29 -> 98.79
A17: 2. Kết quả thực hiện các thương hiệu trong tháng 3/2026
A18: 1. Kết quả thực hiện các thương hiệu :
A19: ➢ SX 50x50 men sân vườn sugar
A20: Kh/TH | B20: Thực Hiện | J20: Tỷ lệ % | L20: Ghi chú
B21: A1 | D21: A | F21: B | H21: Tổng A1+A+B
A22: Luxury | B22: =+[2]T3!$D$24 -> 233358 | D22: 0 | F22: =+[2]T3!$D$26 -> 1960.5 | H22: =+B22+D22+F22 -> 235318.5
B23: =+B22/$H$22*100 -> 99.166874 | C23: =+C22/C34*100 -> #REF! | D23: =+D22/$H$22*100 -> 0 | E23: =+E22/E34*100 -> #REF! | F23: =+F22/$H$22*100 -> 0.83312617 | G23: =+G22/G34*100 -> #REF! | H23: =+H22/$H$22*100 -> 100 | I23: =+I22/I34*100 -> #REF! | J23: =+H22/$H$34*100 -> 56.602528
A24: Green Home | B24: =+[2]T3!$F$24 -> 31834.5 | D24: 0 | F24: =+[2]T3!$F$26 -> 106.5 | H24: =+B24+D24+F24 -> 31941
B25: =+B24/$H$24*100 -> 99.666573 | C25: =+C24/C32*100 -> #DIV/0! | D25: =+D24/$H$24*100 -> 0 | E25: =+E24/E32*100 -> #DIV/0! | F25: =+F24/$H$24*100 -> 0.33342726 | G25: =+G24/G32*100 -> #DIV/0! | H25: =+H24/$H$24*100 -> 100 | I25: =+I24/I32*100 -> #DIV/0! | J25: =+H24/$H$34*100 -> 7.6829545
A26: Crovina | B26: =+[2]T3!$D$31 -> 17817 | D26: 0 | F26: =+[2]T3!$D$33 -> 64.5 | H26: =+B26+D26+F26 -> 17881.5
B27: =+B26/$H$24*100 -> 55.780971 | C27: =+C26/#REF!*100 -> #REF! | D27: =+D26/$H$26*100 -> 0 | F27: =+F26/$H$26*100 -> 0.36070799 | H27: =+H26/$H$26*100 -> 100 | J27: =+H26/$H$34*100 -> 4.3011412
A28: Havira | B28: =+[2]T3!$J$24 -> 54442.5 | D28: 0 | F28: =+[2]T3!$J$26 -> 246 | H28: =+B28+D28+F28 -> 54688.5
B29: =+B28/$H$28*100 -> 99.55018 | C29: =+C28/C30*100 -> #DIV/0! | D29: =+D28/$H$28*100 -> 0 | E29: =+E28/E30*100 -> #DIV/0! | F29: =+F28/$H$28*100 -> 0.44982035 | G29: =+G28/G30*100 -> #DIV/0! | H29: =+H28/$H$28*100 -> 100 | I29: =+I28/I30*100 -> #DIV/0! | J29: =+H28/$H$34*100 -> 13.154543
A30: Xanh Tím | B30: =+[2]T3!$H$24 -> 30355.5 | D30: 0 | F30: =+[2]T3!$H$26 -> 58.5 | H30: =+B30+D30+F30 -> 30414
B31: =+B30/$H$30*100 -> 99.807654 | C31: =+C30/C32*100 -> #DIV/0! | D31: =+D30/$H$30*100 -> 0 | E31: =+E30/E32*100 -> #DIV/0! | F31: =+F30/$H$30*100 -> 0.19234563 | G31: =+G30/G32*100 -> #DIV/0! | H31: =+H30/$H$30*100 -> 100 | I31: =+I30/I32*100 -> #DIV/0! | J31: =+H30/$H$34*100 -> 7.3156564
A32: Top One | B32: =+[2]T3!$L$24 -> 45324 | D32: 0 | F32: =+[2]T3!$L$26 -> 171 | H32: =+B32+D32+F32 -> 45495
B33: =+B32/$H$32*100 -> 99.624135 | C33: =+C32/C34*100 -> #REF! | D33: =+D32/$H$32*100 -> 0 | E33: =+E32/E34*100 -> #REF! | F33: =+F32/$H$32*100 -> 0.37586548 | G33: =+G32/G34*100 -> #REF! | H33: =+H32/$H$32*100 -> 100 | I33: =+I32/I34*100 -> #REF! | J33: =+H32/$H$34*100 -> 10.943177
A34: Tổng | B34: =+B22+B24+B26+B28+B30+B32 -> 413131.5 | C34: =+#REF!+#REF!+#REF!+#REF!+#REF!+C32+C22 -> #REF! | D34: =+D22+D24+D26+D28+D30+D32 -> 0 | E34: =+#REF!+#REF!+#REF!+#REF!+#REF!+E32+E22 -> #REF! | F34: =+F22+F24+F26+F28+F30+F32 -> 2607 | G34: =+#REF!+#REF!+#REF!+#REF!+#REF!+G32+G22 -> #REF! | H34: =+H22+H24+H26+H28+H30+H32 -> 415738.5 | I34: =+#REF!+#REF!+#REF!+#REF!+#REF!+I32+I22 -> #REF! | N34: =+B34+F34 -> 415738.5
B35: =+B34/$H$34*100 -> 99.372923 | C35: =+C23+C33+#REF!+#REF!+#REF!+#REF! -> #REF! | D35: =+D34/$H$34*100 -> 0 | E35: =+E23+E33+#REF!+#REF!+#REF!+#REF! -> #REF! | F35: =+F34/$H$34*100 -> 0.62707688 | G35: =+G23+G33+#REF!+#REF!+#REF!+#REF! -> #REF! | H35: =+H34/$H$34*100 -> 100 | I35: =+I23+I33+#REF!+#REF!+#REF!+#REF! -> #REF! | J35: =+H34/$H$34*100 -> 100
A36: II. Tiêu hao vật tư tháng 03/2026
A37: 1. Tiêu hao vật tư :
A38: ➢ Sản xuất 40x80
A39: STT | B39: Nguyên liệu, vật tư | D39: ĐVT | E39: Định mức | F39: Thực tế | G39: Lượng SD | I39: -Giảm ĐM | J39: + Vượt ĐM | K39: Ghi chú | N39: SL | O39: =+O40+O41 -> 0 | P39: C | Q39: =+Q40+Q41 -> 0
A40: 1 | B40: Nguyên liệu xương | D40: kg | E40: 21.01 | F40: =+G40/$O$39 -> #DIV/0! | I40: =+(E40-F40)*$O$39 -> #DIV/0! | K40: Bột phế và gạch phế 158,585.07kg | N40: Panson
A41: 2 | B41: Men EWP | D41: kg | E41: 0.483 | F41: =+G41/$O$39 -> #DIV/0! | I41: =+(E41-F41)*$O$39 -> #DIV/0!
A42: 3 | B42: Men GWP | D42: kg | E42: 0.54 | F42: =+G42/$O$39 -> #DIV/0! | I42: =+(E42-F42)*$O$39 -> #DIV/0!
...

Sheet T4.2026
A1: CÔNG TY CỔ PHẦN GẠCH MEN PHƯƠNG NAM
A2: PHÂN XƯỞNG SẢN XUẤT DC2
A4: BÁO CÁO KẾT QUẢ SẢN XUẤT DÂY CHUYỀN SỐ 2 THÁNG 4 NĂM 2026
A6: I. Kết quả sản xuất tháng 04 năm 2026:
A7: I. Kết quả sản lượng – Chất lượng – Thu hồi ∑AB/ép :
A8: 1. Kết quả thực hiện Sản lượng – Chất lượng – Thu hồi ∑AB/ép
A9: Kích thước | C9: Sản Lượng Ép | D9: Sản lượng thu hồi | G9: Tổng (A1+A+B) | H9: Số ngày sx | I9: TB/ngày | J9: A/ép (%) | K9: C | L9: Hủy | M9: Dừng ép | N9: ok
A10: KH/TH | B10: ĐVT | D10: A1 | E10: A | F10: B | I10: m2 | K10: C/ép | L10: Hủy/ép | M10: phút/ngày
A11: KẾ HOẠCH 50*50 | B11: m2 | C11: =+G11*100/J12 -> 196980 | D11: =+$G$11*D12/100 -> 181457.98 | E11: =+$G$11*E12/100 -> 5791.212 | F11: =+$G$11*F12/100 -> 5791.212 | G11: =+I11*H11 -> 193040.4 | H11: 14 | I11: =21*0.5*1340*0.98 -> 13788.6
B12: % | D12: 94 | E12: 3 | F12: 3 | G12: 100 | J12: 98 | K12: 2 | M12: 100 | P12: =10.6*418800 -> 4439280
A13: THỰC HIỆN 50*50 | B13: m2 | C13: 209653 | D13: 207028.5 | E13: 0 | F13: 1215 | G13: =SUM(D13:F13) -> 208243.5 | H13: 14 | I13: =+G13/H13 -> 14874.536 | K13: 729 | L13: 603 | P13: =+P12/10.9 -> 407273.39
B14: % | D14: =+D13/G13*100 -> 99.416548 | E14: =+E13/G13*100 -> 0 | F14: =+F13/G13*100 -> 0.58345158 | G14: =SUM(D14:F14) -> 100 | J14: =+G13/C13*100 -> 99.327699 | K14: =100-J14 -> 0.67230137 | M14: 75 | P14: =+P13*2390 -> 9.7338341e+08
A15: So sánh TH/KH 50*50 | B15: m2 | C15: =+C13-C11 -> 12673 | D15: =+D13-D11 -> 25570.524 | E15: =+(E13-E11) -> -5791.212 | F15: =+F13-F11 -> -4576.212 | G15: =SUM(D15:F15) -> 15203.1 | P15: =+P14/418800 -> 2324.2202
B16: % | D16: =+D14-D12 -> 5.4165484 | E16: =+E14-E12 -> -3 | F16: =+F14-F12 -> -2.4165484 | G16: 0 | N16: =97.5+1.29 -> 98.79
A17: KẾ HOẠCH 40*80 | B17: m2 | C17: =+G17*100/J18 -> 219744 | D17: =+$G$17*D18/100 -> 191660.72 | E17: =+$G$17*E18/100 -> 17227.93 | F17: =+$G$17*F18/100 -> 6460.4736 | G17: =+I17*H17 -> 215349.12 | H17: 15 | I17: =10.9*0.96*1400*0.98 -> 14356.608
B18: % | D18: 89 | E18: 8 | F18: 3 | G18: 100 | J18: 98 | K18: 2 | M18: 40
A19: THỰC HIỆN 40*80 | B19: m2 | C19: 231114 | D19: 206841.6 | E19: 0 | F19: 17892.8 | G19: =+F19+D19 -> 224734.4 | H19: 15.5 | I19: =G19/H19 -> 14498.994 | K19: 1277 | L19: 2254
B20: % | D20: =+D19/G19*100 -> 92.038246 | E20: =+E19/G19*100 -> 0 | F20: =+F19/G19*100 -> 7.961754 | G20: =SUM(D20:F20) -> 100 | J20: =+G19/C19*100 -> 97.239631 | K20: 1 | M20: 42
A21: So sánh TH/KH 40*80 | B21: m2 | C21: =+C19-C17 -> 11370 | D21: =+D19-D17 -> 15180.883 | E21: =+(E19-E17) -> -17227.93 | F21: =+F19-F17 -> 11432.326 | G21: =SUM(D21:F21) -> 9385.28
B22: % | D22: =+D20-D18 -> 3.038246 | E22: =+E20-E18 -> -8 | F22: =+F20-F18 -> 4.961754 | G22: 0 | N22: =97.5+1.29 -> 98.79
A23: 2. Kết quả thực hiện các thương hiệu trong tháng 4/2026
A24: 1. Kết quả thực hiện các thương hiệu :
A25: ➢ SX 50x50 men sân vườn sugar
A26: Kh/TH | B26: Thực Hiện | J26: Tỷ lệ % | L26: Ghi chú | N26: ok
B27: A1 | D27: A | F27: B | H27: Tổng A1+A+B
A28: Luxury | B28: =+[3]T4!$D$24 -> 78493.5 | D28: 0 | F28: =+[3]T4!$D$26 -> 409.5 | H28: =+B28+D28+F28 -> 78903
B29: =+B28/$H$28*100 -> 99.481008 | C29: =+C28/C44*100 -> #REF! | D29: =+D28/$H$28*100 -> 0 | E29: =+E28/E44*100 -> #REF! | F29: =+F28/$H$28*100 -> 0.51899167 | G29: =+G28/G44*100 -> #REF! | H29: =+H28/$H$28*100 -> 100 | I29: =+I28/I44*100 -> #REF! | J29: =+H28/$H$44*100 -> 37.889778
A30: Green Home | B30: =+[3]T4!$F$24 -> 9565.5 | D30: 0 | F30: =+[3]T4!$F$26 -> 91.5 | H30: =+B30+D30+F30 -> 9657
B31: =+B30/$H$30*100 -> 99.052501 | C31: =+C30/C38*100 -> #DIV/0! | D31: =+D30/$H$30*100 -> 0 | E31: =+E30/E38*100 -> #DIV/0! | F31: =+F30/$H$30*100 -> 0.94749922 | G31: =+G30/G38*100 -> #DIV/0! | H31: =+H30/$H$30*100 -> 100 | I31: =+I30/I38*100 -> #DIV/0! | J31: =+H30/$H$44*100 -> 4.6373596
A32: Xanh Tím | B32: =+[3]T4!$H$24 -> 23089.5 | D32: 0 | F32: =+[3]T4!$H$26 -> 67.5 | H32: =+B32+D32+F32 -> 23157
B33: =+B32/$H$30*100 -> 239.09599 | C33: =+C32/#REF!*100 -> #REF! | D33: =+D32/$H$32*100 -> 0 | F33: =+F32/$H$32*100 -> 0.29148853 | H33: =+H32/$H$32*100 -> 100 | J33: =+H32/$H$44*100 -> 11.120155
A34: Havira | B34: =+[3]T4!$J$24 -> 25012.5 | D34: 0 | F34: =+[3]T4!$J$26 -> 331.5 | H34: =+B34+D34+F34 -> 25344
B35: =+B34/$H$34*100 -> 98.691998 | C35: =+C34/C36*100 -> #DIV/0! | D35: =+D34/$H$34*100 -> 0 | E35: =+E34/E36*100 -> #DIV/0! | F35: =+F34/$H$34*100 -> 1.3080019 | G35: =+G34/G36*100 -> #DIV/0! | H35: =+H34/$H$34*100 -> 100 | I35: =+I34/I36*100 -> #DIV/0! | J35: =+H34/$H$44*100 -> 12.170368
A36: Top One | B36: =+[3]T4!$L$24 -> 26017.5 | D36: 0 | F36: =+[3]T4!$L$26 -> 147 | H36: =+B36+D36+F36 -> 26164.5
B37: =+B36/$H$36*100 -> 99.43817 | C37: =+C36/C38*100 -> #DIV/0! | D37: =+D36/$H$36*100 -> 0 | E37: =+E36/E38*100 -> #DIV/0! | F37: =+F36/$H$36*100 -> 0.56182996 | G37: =+G36/G38*100 -> #DIV/0! | H37: =+H36/$H$36*100 -> 100 | I37: =+I36/I38*100 -> #DIV/0! | J37: =+H36/$H$44*100 -> 12.564378
A38: Crovina | B38: =+[3]T4!$D$31 -> 13810.5 | D38: 0 | F38: =+[3]T4!$D$33 -> 30 | H38: =+B38+D38+F38 -> 13840.5
B39: =+B38/$H$38*100 -> 99.783245 | C39: =+C38/C44*100 -> #REF! | D39: =+D38/$H$38*100 -> 0 | E39: =+E38/E44*100 -> #REF! | F39: =+F38/$H$38*100 -> 0.21675518 | G39: =+G38/G44*100 -> #REF! | H39: =+H38/$H$38*100 -> 100 | I39: =+I38/I44*100 -> #REF! | J39: =+H38/$H$44*100 -> 6.6463059
A40: Vidona | B40: =+[3]T4!$F$31 -> 15009 | D40: 0 | F40: =+[3]T4!$F$33 -> 54 | H40: =+B40+D40+F40 -> 15063
B41: =+B40/$H$36*100 -> 57.363986 | C41: =+C40/C42*100 -> #DIV/0! | D41: =+D40/$H$36*100 -> 0 | E41: =+E40/E42*100 -> #DIV/0! | F41: =+F40/$H$36*100 -> 0.20638652 | G41: =+G40/G42*100 -> #DIV/0! | H41: =+H40/$H$36*100 -> 57.570372 | I41: =+I40/I42*100 -> #DIV/0! | J41: =+H40/$H$44*100 -> 7.233359
A42: Karpo | B42: =+[3]T4!$H$31 -> 16030.5 | D42: 0 | F42: =+[3]T4!$H$33 -> 84 | H42: =+B42+D42+F42 -> 16114.5
...

Sheet T5.2026
A1: CÔNG TY CỔ PHẦN GẠCH MEN PHƯƠNG NAM
A2: PHÂN XƯỞNG SẢN XUẤT DC2
A4: BÁO CÁO KẾT QUẢ SẢN XUẤT DÂY CHUYỀN SỐ 2 THÁNG 5 NĂM 2026
A6: I. Kết quả sản xuất tháng 05 năm 2026:
A7: I. Kết quả sản lượng – Chất lượng – Thu hồi ∑AB/ép :
A8: 1. Kết quả thực hiện Sản lượng – Chất lượng – Thu hồi ∑AB/ép
A9: Kích thước | C9: Sản Lượng Ép | D9: Sản lượng thu hồi | G9: Tổng (A1+A+B) | H9: Số ngày sx | I9: TB/ngày | J9: A/ép (%) | K9: C | L9: Hủy | M9: Dừng ép
A10: KH/TH | B10: ĐVT | D10: A1 | E10: A | F10: B | I10: m2 | K10: C/ép | L10: Hủy/ép | M10: phút/ngày
A11: KẾ HOẠCH 50*50 | B11: m2 | C11: =+G11*100/J12 -> 196980 | D11: =+$G$11*D12/100 -> 181457.98 | E11: =+$G$11*E12/100 -> 5791.212 | F11: =+$G$11*F12/100 -> 5791.212 | G11: =+I11*H11 -> 193040.4 | H11: 14 | I11: =21*0.5*1340*0.98 -> 13788.6
B12: % | D12: 94 | E12: 3 | F12: 3 | G12: 100 | J12: 98 | K12: 2 | M12: 100 | P12: =10.6*418800 -> 4439280
A13: THỰC HIỆN 50*50 | B13: m2 | C13: 209653 | D13: 207028.5 | E13: 0 | F13: 1215 | G13: =SUM(D13:F13) -> 208243.5 | H13: 14 | I13: =+G13/H13 -> 14874.536 | K13: 729 | L13: 603 | P13: =+P12/10.9 -> 407273.39
B14: % | D14: =+D13/G13*100 -> 99.416548 | E14: =+E13/G13*100 -> 0 | F14: =+F13/G13*100 -> 0.58345158 | G14: =SUM(D14:F14) -> 100 | J14: =+G13/C13*100 -> 99.327699 | K14: =100-J14 -> 0.67230137 | M14: 75 | P14: =+P13*2390 -> 9.7338341e+08
A15: So sánh TH/KH 50*50 | B15: m2 | C15: =+C13-C11 -> 12673 | D15: =+D13-D11 -> 25570.524 | E15: =+(E13-E11) -> -5791.212 | F15: =+F13-F11 -> -4576.212 | G15: =SUM(D15:F15) -> 15203.1 | P15: =+P14/418800 -> 2324.2202
B16: % | D16: =+D14-D12 -> 5.4165484 | E16: =+E14-E12 -> -3 | F16: =+F14-F12 -> -2.4165484 | G16: 0 | N16: =97.5+1.29 -> 98.79
A17: KẾ HOẠCH 40*80 | B17: m2 | C17: =+G17*100/J18 -> 454137.6 | D17: =+G17*D18/100 -> 400549.36 | E17: =+G17*E18/100 -> 31153.839 | F17: =+G17*F18/100 -> 13351.645 | G17: =+I17*H17 -> 445054.85 | H17: 31 | I17: =10.9*0.96*1400*0.98 -> 14356.608
B18: % | D18: 90 | E18: 7 | F18: 3 | G18: 100 | J18: 98 | K18: 2 | M18: 40
A19: THỰC HIỆN 40*80 nung 2 lần | B19: m2 | C19: 149733 | D19: 142680 | E19: 0 | F19: 7974.4 | G19: =+F19+D19 -> 150654.4 | H19: 10 | I19: =G19/H19 -> 15065.44 | K19: 574.4 | L19: 732.8
B20: % | D20: =+D19/G19*100 -> 94.706826 | E20: =+E19/G19*100 -> 0 | F20: =+F19/G19*100 -> 5.2931743 | G20: =SUM(D20:F20) -> 100 | J20: =+G19/C19*100 -> 100.61536 | K20: 1 | M20: 42
A21: THỰC HIỆN 40*80 nung 1.5 lần | B21: m2 | C21: 316406 | D21: 292179.2 | E21: 0 | F21: 16897.6 | G21: =+F21+D21 -> 309076.8 | H21: 21 | I21: =G21/H21 -> 14717.943 | K21: 1332.8 | L21: 1297.6
B22: % | D22: =+D21/G21*100 -> 94.53288 | E22: =+E21/G21*100 -> 0 | F22: =+F21/G21*100 -> 5.4671201 | G22: =SUM(D22:F22) -> 100 | J22: =+G21/C21*100 -> 97.683609 | K22: 1 | M22: 15
A23: TỔNG THỰC HIỆN 40*80 | B23: m2 | C23: =+C21+C19 -> 466139 | D23: =+D19+D21 -> 434859.2 | E23: 0 | F23: =+F19+F21 -> 24872 | G23: =+F23+D23 -> 459731.2 | H23: 31 | I23: =G23/H23 -> 14830.039 | K23: =+K21+K19 -> 1907.2 | L23: =+L21+L19 -> 2030.4
B24: % | D24: =+D23/G23*100 -> 94.589882 | E24: =+E23/G23*100 -> 0 | F24: =+F23/G23*100 -> 5.4101179 | G24: =SUM(D24:F24) -> 100 | J24: =+G23/C23*100 -> 98.625346 | K24: 1 | M24: =(M20/H23*H19)+(M22/H23*H21) -> 23.709677
A25: So sánh TH/KH 40*80 | B25: m2 | C25: =+C23-C17 -> 12001.4 | D25: =+D23-D17 -> 34309.837 | E25: =+E23-E17 -> -31153.839 | F25: =+F23-F17 -> 11520.355 | G25: =+G23-G17 -> 14676.352
B26: % | D26: =+D20-D18 -> 4.7068257 | E26: =+E20-E18 -> -7 | F26: =+F20-F18 -> 2.2931743 | G26: 0 | N26: =97.5+1.29 -> 98.79
A27: 2. Kết quả thực hiện các thương hiệu trong tháng 5/2026
A28: 1. Kết quả thực hiện các thương hiệu :
A29: ➢ SX 40x80 men Panson (Nung 2 lần):
A30: Kh/TH | B30: Thực Hiện | J30: Tỷ lệ % | L30: Ghi chú | O30: OK
B31: A1 | D31: A | F31: B | H31: Tổng A1+A+B
A32: Luxury | B32: =+[4]T5.2026!$D$24 -> 75995.2 | F32: =+[4]T5.2026!$D$26 -> 4536 | H32: =+B32+D32+F32 -> 80531.2
B33: =+B32/$H$32*100 -> 94.3674 | C33: =+C32/C48*100 -> #REF! | D33: =+D32/$H$32*100 -> 0 | E33: =+E32/E48*100 -> #REF! | F33: =+F32/$H$32*100 -> 5.6325995 | G33: =+G32/G48*100 -> #REF! | H33: =+H32/$H$32*100 -> 100 | I33: =+I32/I48*100 -> #REF! | J33: =+H32/$H$48*100 -> 53.454264
A34: Green Home | B34: =+[4]T5.2026!$F$24 -> 3136 | F34: =+[4]T5.2026!$F$26 -> 128 | H34: =+B34+D34+F34 -> 3264
B35: =+B34/$H$34*100 -> 96.078431 | C35: =+C34/C42*100 -> #DIV/0! | D35: =+D34/$H$34*100 -> 0 | E35: =+E34/E42*100 -> #DIV/0! | F35: =+F34/$H$34*100 -> 3.9215686 | G35: =+G34/G42*100 -> #DIV/0! | H35: =+H34/$H$34*100 -> 100 | I35: =+I34/I42*100 -> #DIV/0! | J35: =+H34/$H$48*100 -> 2.1665481
A36: Green Era | B36: =+[4]T5.2026!$H$24 -> 12752 | F36: =+[4]T5.2026!$H$26 -> 920 | H36: =+B36+D36+F36 -> 13672
B37: =+B36/$H$34*100 -> 390.68627 | C37: =+C36/#REF!*100 -> #REF! | D37: =+D36/$H$36*100 -> 0 | F37: =+F36/$H$36*100 -> 6.7290813 | H37: =+H36/$H$36*100 -> 100 | J37: =+H36/$H$48*100 -> 9.0750751
A38: Havira | B38: =+[4]T5.2026!$N$24 -> 4972.8 | F38: =+[4]T5.2026!$N$26 -> 406.4 | H38: =+B38+D38+F38 -> 5379.2
B39: =+B38/$H$38*100 -> 92.444973 | C39: =+C38/C40*100 -> #DIV/0! | D39: =+D38/$H$38*100 -> 0 | E39: =+E38/E40*100 -> #DIV/0! | F39: =+F38/$H$38*100 -> 7.5550268 | G39: =+G38/G40*100 -> #DIV/0! | H39: =+H38/$H$38*100 -> 100 | I39: =+I38/I40*100 -> #DIV/0! | J39: =+H38/$H$48*100 -> 3.5705562
A40: Top One | B40: =+[4]T5.2026!$P$24 -> 8035.2 | F40: =+[4]T5.2026!$P$26 -> 387.2 | H40: =+B40+D40+F40 -> 8422.4
B41: =+B40/$H$40*100 -> 95.402736 | C41: =+C40/C42*100 -> #DIV/0! | D41: =+D40/$H$40*100 -> 0 | E41: =+E40/E42*100 -> #DIV/0! | F41: =+F40/$H$40*100 -> 4.5972644 | G41: =+G40/G42*100 -> #DIV/0! | H41: =+H40/$H$40*100 -> 100 | I41: =+I40/I42*100 -> #DIV/0! | J41: =+H40/$H$48*100 -> 5.5905437
A42: Crovina | B42: =+[4]T5.2026!$D$31 -> 13889.6 | F42: =+[4]T5.2026!$D$33 -> 475.2 | H42: =+B42+D42+F42 -> 14364.8
...

Sheet T6.2026
A1: CÔNG TY CỔ PHẦN GẠCH MEN PHƯƠNG NAM
A2: PHÂN XƯỞNG SẢN XUẤT DC2
A4: BÁO CÁO KẾT QUẢ SẢN XUẤT DÂY CHUYỀN SỐ 2 THÁNG 6 NĂM 2026
A6: I. Kết quả sản xuất tháng 06 năm 2026:
A7: I. Kết quả sản lượng – Chất lượng – Thu hồi ∑AB/ép :
A8: 1. Kết quả thực hiện Sản lượng – Chất lượng – Thu hồi ∑AB/ép
A9: Kích thước | C9: Sản Lượng Ép | D9: Sản lượng thu hồi | G9: Tổng (A1+A+B) | H9: Số ngày sx | I9: TB/ngày | J9: A/ép (%) | K9: C | L9: Hủy | M9: Dừng ép
A10: KH/TH | B10: ĐVT | D10: A1 | E10: A | F10: B | I10: m2 | K10: C/ép | L10: Hủy/ép | M10: phút/ngày
A11: KẾ HOẠCH 50*50 | B11: m2 | C11: =+G11*100/J12 -> 196980 | D11: =+$G$11*D12/100 -> 181457.98 | E11: =+$G$11*E12/100 -> 5791.212 | F11: =+$G$11*F12/100 -> 5791.212 | G11: =+I11*H11 -> 193040.4 | H11: 14 | I11: =21*0.5*1340*0.98 -> 13788.6
B12: % | D12: 94 | E12: 3 | F12: 3 | G12: 100 | J12: 98 | K12: 2 | M12: 100 | P12: =10.6*418800 -> 4439280
A13: THỰC HIỆN 50*50 | B13: m2 | C13: 209653 | D13: 207028.5 | E13: 0 | F13: 1215 | G13: =SUM(D13:F13) -> 208243.5 | H13: 14 | I13: =+G13/H13 -> 14874.536 | K13: 729 | L13: 603 | P13: =+P12/10.9 -> 407273.39
B14: % | D14: =+D13/G13*100 -> 99.416548 | E14: =+E13/G13*100 -> 0 | F14: =+F13/G13*100 -> 0.58345158 | G14: =SUM(D14:F14) -> 100 | J14: =+G13/C13*100 -> 99.327699 | K14: =100-J14 -> 0.67230137 | M14: 75 | P14: =+P13*2390 -> 9.7338341e+08
A15: So sánh TH/KH 50*50 | B15: m2 | C15: =+C13-C11 -> 12673 | D15: =+D13-D11 -> 25570.524 | E15: =+(E13-E11) -> -5791.212 | F15: =+F13-F11 -> -4576.212 | G15: =SUM(D15:F15) -> 15203.1 | P15: =+P14/418800 -> 2324.2202
B16: % | D16: =+D14-D12 -> 5.4165484 | E16: =+E14-E12 -> -3 | F16: =+F14-F12 -> -2.4165484 | G16: 0 | N16: =97.5+1.29 -> 98.79
A17: KẾ HOẠCH 40*80 | B17: m2 | C17: =+G17*100/J18 -> 424838.4 | D17: =+G17*D18/100 -> 374707.47 | E17: =+G17*E18/100 -> 29143.914 | F17: =+G17*F18/100 -> 12490.249 | G17: =+I17*H17 -> 416341.63 | H17: 29 | I17: =10.9*0.96*1400*0.98 -> 14356.608 | K17: 4395
B18: % | D18: 90 | E18: 7 | F18: 3 | G18: 100 | J18: 98 | K18: =100-J18 -> 2 | M18: 40
A19: KẾ HOẠCH 50*50 | B19: m2 | C19: =+G19*100/J20 -> 7035 | D19: =+G19*D20/100 -> 6480.642 | E19: =+G19*E20/100 -> 206.829 | F19: =+G19*F20/100 -> 206.829 | G19: =+I19*H19 -> 6894.3 | H19: 0.5 | I19: =21*0.5*1340*0.98 -> 13788.6 | K19: 4080
B20: % | D20: 94 | E20: 3 | F20: 3 | G20: 100 | J20: 98 | K20: =100-J20 -> 2 | M20: 100
A21: THỰC HIỆN 40*80 | B21: m2 | C21: 435135 | D21: 408598.4 | E21: 0 | F21: 22238.4 | G21: =+F21+D21 -> 430836.8 | H21: 29 | I21: =G21/H21 -> 14856.441 | K21: 1907 | L21: 2030
B22: % | D22: =+D21/G21*100 -> 94.838324 | E22: =+E21/G21*100 -> 0 | F22: =+F21/G21*100 -> 5.1616761 | G22: =SUM(D22:F22) -> 100 | J22: =+G21/C21*100 -> 99.012215 | K22: =100-J22 -> 0.9877854 | M22: 25
A23: THỰC HIỆN 50*50 | B23: m2 | C23: 7270 | D23: 5472 | E23: 0 | F23: 199.5 | G23: =+F23+D23 -> 5671.5 | H23: 0.5 | I23: =G23/H23 -> 11343 | K23: 26 | L23: 45
B24: % | D24: =+D23/G23*100 -> 96.482412 | E24: =+E23/G23*100 -> 0 | F24: =+F23/G23*100 -> 3.5175879 | G24: =SUM(D24:F24) -> 100 | J24: =+G23/C23*100 -> 78.01238 | K24: =100-J24 -> 21.98762 | M24: 48
A25: So sánh TH/KH 40*80 | B25: m2 | C25: =+C21-C17 -> 10296.6 | D25: =+D21-D17 -> 33890.931 | E25: =+E21-E17 -> -29143.914 | F25: =+F21-F17 -> 9748.151 | G25: =+D25+F25 -> 43639.082
B26: % | D26: =+D22-D18 -> 4.8383239 | E26: =+E22-E18 -> -7 | F26: =+F22-F18 -> 2.1616761 | N26: =97.5+1.29 -> 98.79
A27: So sánh TH/KH 50*50 | B27: m2 | C27: =+C23-C17 -> -417568.4 | D27: =+D23-D17 -> -369235.47 | E27: =+E23-E17 -> -29143.914 | F27: =+F23-F17 -> -12290.749 | G27: =+D27+F27 -> -381526.22
B28: % | D28: =+D24-D20 -> 2.4824121 | E28: =+E24-E20 -> -3 | F28: =+F24-F20 -> 0.51758794 | G28: 0 | N28: =97.5+1.29 -> 98.79
A29: 2. Kết quả thực hiện các thương hiệu trong tháng 6/2026
A30: 1. Kết quả thực hiện các thương hiệu :
A31: ➢ SX 40x80 men Panson :
A32: Kh/TH | B32: Thực Hiện | J32: Tỷ lệ % | L32: Ghi chú | O32: OK
B33: A1 | D33: A | F33: B | H33: Tổng A1+A+B
A34: Luxury | B34: 117024 | F34: 9840 | H34: =+B34+D34+F34 -> 126864
B35: =+B34/$H$34*100 -> 92.243663 | C35: =+C34/C56*100 -> #REF! | D35: =+D34/$H$34*100 -> 0 | E35: =+E34/E56*100 -> #REF! | F35: =+F34/$H$34*100 -> 7.7563375 | G35: =+G34/G56*100 -> #REF! | H35: =+H34/$H$34*100 -> 100 | I35: =+I34/I56*100 -> #REF! | J35: =+H34/$H$56*100 -> 29.445843
A36: Green Home | B36: 3388.8 | F36: 179.2 | H36: =+B36+D36+F36 -> 3568
B37: =+B36/$H$36*100 -> 94.977578 | C37: =+C36/C42*100 -> #DIV/0! | D37: =+D36/$H$36*100 -> 0 | E37: =+E36/E42*100 -> #DIV/0! | F37: =+F36/$H$36*100 -> 5.0224215 | G37: =+G36/G42*100 -> #DIV/0! | H37: =+H36/$H$36*100 -> 100 | I37: =+I36/I42*100 -> #DIV/0! | J37: =+H36/$H$56*100 -> 0.82815274
A38: Vidona | B38: 11126.4 | F38: 785.6 | H38: =+B38+D38+F38 -> 11912
B39: =+B38/$H$38*100 -> 93.40497 | C39: =+C38/C44*100 -> #DIV/0! | D39: =+D38/$H$38*100 -> 0 | E39: =+E38/E44*100 -> #DIV/0! | F39: =+F38/$H$38*100 -> 6.5950302 | G39: =+G38/G44*100 -> #DIV/0! | H39: =+H38/H38*100 -> 100 | I39: =+I38/#REF!*100 -> #REF! | J39: =+H38/$H$56*100 -> 2.7648418
A40: Havira | B40: 23640 | F40: 1057.6 | H40: =+B40+D40+F40 -> 24697.6
B41: =+B40/$H$40*100 -> 95.717803 | C41: =+C40/#REF!*100 -> #REF! | D41: =+D40/$H$40*100 -> 0 | E41: =+E40/#REF!*100 -> #REF! | F41: =+F40/$H$40*100 -> 4.2821975 | G41: =+G40/#REF!*100 -> #REF! | H41: =+H40/$H$40*100 -> 100 | I41: =+I40/#REF!*100 -> #REF! | J41: =+H40/$H$56*100 -> 5.732451
A42: Crovina | B42: 35075.2 | F42: 1182.4 | H42: =+B42+D42+F42 -> 36257.6
...

Sheet 6 tháng đầu năm
A1: CÔNG TY CỔ PHẦN GẠCH MEN PHƯƠNG NAM
A2: PHÂN XƯỞNG SẢN XUẤT DC2
A4: BÁO CÁO KẾT QUẢ SẢN XUẤT DÂY CHUYỀN SỐ 2 6 THÁNG ĐẦU NĂM 2026
A6: I. Kết quả sản xuất 6 tháng đầu năm 2026:
A7: I. Kết quả sản lượng – Chất lượng – Thu hồi ∑AB/ép :
A8: 1. Kết quả thực hiện Sản lượng – Chất lượng – Thu hồi ∑AB/ép
A9: Kích thước | C9: Sản Lượng Ép | D9: Sản lượng thu hồi | G9: Tổng (A1+A+B) | H9: Số ngày sx | I9: TB/ngày | J9: A/ép (%) | K9: C | L9: Hủy | M9: Dừng ép | O9: ok | P9: =+C17+C23 -> 1912457.4
A10: KH/TH | B10: ĐVT | D10: A1 | E10: A | F10: B | I10: m2 | K10: C/ép | L10: Hủy/ép | M10: phút/ngày | O10: =+T5.2026!G17+T4.2026!G17+T1.2026!G11 -> 885628.97
A11: KẾ HOẠCH 50*50 | B11: m2 | C11: =+G11*100/J12 -> 196980 | D11: =+$G$11*D12/100 -> 181457.98 | E11: =+$G$11*E12/100 -> 5791.212 | F11: =+$G$11*F12/100 -> 5791.212 | G11: =+I11*H11 -> 193040.4 | H11: 14 | I11: =21*0.5*1340*0.98 -> 13788.6
B12: % | D12: 94 | E12: 3 | F12: 3 | G12: 100 | J12: 98 | K12: 2 | M12: 100 | P12: =10.6*418800 -> 4439280
A13: THỰC HIỆN 50*50 | B13: m2 | C13: 209653 | D13: 207028.5 | E13: 0 | F13: 1215 | G13: =SUM(D13:F13) -> 208243.5 | H13: 14 | I13: =+G13/H13 -> 14874.536 | K13: 729 | L13: 603 | P13: =+P12/10.9 -> 407273.39
B14: % | D14: =+D13/G13*100 -> 99.416548 | E14: =+E13/G13*100 -> 0 | F14: =+F13/G13*100 -> 0.58345158 | G14: =SUM(D14:F14) -> 100 | J14: =+G13/C13*100 -> 99.327699 | K14: =100-J14 -> 0.67230137 | M14: 75 | P14: =+P13*2390 -> 9.7338341e+08
A15: So sánh TH/KH 50*50 | B15: m2 | C15: =+C13-C11 -> 12673 | D15: =+D13-D11 -> 25570.524 | E15: =+(E13-E11) -> -5791.212 | F15: =+F13-F11 -> -4576.212 | G15: =SUM(D15:F15) -> 15203.1 | P15: =+P14/418800 -> 2324.2202
B16: % | D16: =+D14-D12 -> 5.4165484 | E16: =+E14-E12 -> -3 | F16: =+F14-F12 -> -2.4165484 | G16: 0 | N16: =97.5+1.29 -> 98.79
A17: KẾ HOẠCH 40*80 | B17: m2 | C17: =+T1.2026!C11+T4.2026!C17+T5.2026!C17+T6.2026!C17 -> 1328541.4 | D17: =+$G$17*D18/100 -> 1171773.5 | E17: =+$G$17*E18/100 -> 91137.942 | F17: =+$G$17*F18/100 -> 39059.118 | G17: =+T5.2026!G17+T4.2026!G17+T1.2026!G11+T6.2026!G17 -> 1301970.6 | H17: =+T5.2026!H17+T4.2026!H17+T1.2026!H11+T6.2026!H17 -> 90 | I17: =+G17/H17 -> 14466.34 | K17: =+C17-G17 -> 26570.829 | O17: =+D17+E17+F17 -> 1301970.6
B18: % | D18: 90 | E18: 7 | F18: 3 | G18: 100 | J18: 98 | K18: 2 | M18: 40
A19: THỰC HIỆN 40*80 | B19: m2 | C19: =+T5.2026!C23+T4.2026!C19+T1.2026!C13+T6.2026!C21 -> 1353363 | D19: =+T5.2026!D23+T4.2026!D19+T1.2026!D13+T6.2026!D21 -> 1259672 | E19: 0 | F19: =+T5.2026!F23+T4.2026!F19+T1.2026!F13+T6.2026!F21 -> 75569.6 | G19: =+F19+D19 -> 1335241.6 | H19: =+T6.2026!H21+T5.2026!H23+T4.2026!H19+T1.2026!H13 -> 90.5 | I19: =G19/H19 -> 14754.051 | K19: =+T5.2026!K23+T4.2026!K19+T1.2026!K13+T6.2026!K21 -> 5795.2 | L19: =+T5.2026!L23+T4.2026!L19+T1.2026!L13+T6.2026!L21 -> 7277 | O19: =+T5.2026!G23+T4.2026!G19+T1.2026!G13 -> 904404.8
B20: % | D20: =+D19/G19*100 -> 94.34038 | E20: =+E19/G19*100 -> 0 | F20: =+F19/G19*100 -> 5.65962 | G20: =SUM(D20:F20) -> 100 | J20: =+G19/C19*100 -> 98.66101 | K20: =100-J20 -> 1.3389904 | M20: 42
A21: So sánh TH/KH 40*80 | B21: m2 | C21: =+C19-C17 -> 24821.571 | D21: =+D19-D17 -> 87898.46 | E21: =+E19-E17 -> -91137.942 | F21: =+F19-F17 -> 36510.482 | G21: =+G19-G17 -> 33271
B22: % | D22: =+D14-D12 -> 5.4165484 | E22: =+E14-E12 -> -3 | F22: =+F14-F12 -> -2.4165484 | G22: 0 | N22: =97.5+1.29 -> 98.79
A23: KẾ HOẠCH 50*50 | B23: m2 | C23: =+T4.2026!C11+T3.2026!C11+T6.2026!C19 -> 583916 | D23: =+T4.2026!D11+T3.2026!D11+T6.2026!D19 -> 537903.62 | E23: =+T4.2026!E11+T3.2026!E11+T6.2026!E19 -> 17167.041 | F23: =+T4.2026!F11+T3.2026!F11+T6.2026!F19 -> 17167.041 | G23: =+F23+D23+E23 -> 572237.7 | H23: =+T4.2026!H11+T3.2026!H11+T6.2026!H23 -> 42.5 | I23: =21*0.5*1340*0.98 -> 13788.6 | K23: =+C23-G23 -> 11678.3 | O23: =+T4.2026!G11+T3.2026!G11 -> 565343.4
B24: % | D24: =+D23/G23*100 -> 94.000031 | E24: =+E23/G23*100 -> 2.9999843 | F24: =+F23/G23*100 -> 2.9999843 | G24: =SUM(D24:F24) -> 100 | J24: =+G23/C23*100 -> 98.000003 | K24: 2 | M24: 100
A25: THỰC HIỆN 50*50 | B25: m2 | C25: =+T4.2026!C13+T3.2026!C13+T6.2026!C23 -> 638090 | D25: =+T4.2026!D13+T3.2026!D13+T6.2026!D23 -> 625632 | E25: 0 | F25: =+T4.2026!F13+T3.2026!F13+T6.2026!F23 -> 4021.5 | G25: =+F25+D25 -> 629653.5 | H25: =+T6.2026!H23+T4.2026!H13+T3.2026!H13 -> 42.5 | I25: =G25/H25 -> 14815.376 | K25: =+T4.2026!K13+T3.2026!K13+T6.2026!K23 -> 1925 | L25: =+T4.2026!L13+T3.2026!L13+T6.2026!L23 -> 1701 | O25: =+T4.2026!G13+T3.2026!G13 -> 623982
B26: % | D26: =+D25/G25*100 -> 99.361315 | E26: =+E25/G25*100 -> 0 | F26: =+F25/G25*100 -> 0.63868461 | G26: =SUM(D26:F26) -> 100 | J26: =+G25/C25*100 -> 98.677851 | K26: =100-J26 -> 1.3221489 | M26: 78
A27: So sánh TH/KH 50*50 | B27: m2 | C27: =+C25-C17 -> -690451.43 | D27: =+D25-D17 -> -546141.54 | E27: =+E25-E17 -> -91137.942 | F27: =+F25-F17 -> -35037.618 | G27: =+G25-G17 -> -672317.1
B28: % | D28: =+D20-D18 -> 4.34038 | E28: =+E20-E18 -> -7 | F28: =+F20-F18 -> 2.65962 | G28: 0 | N28: =97.5+1.29 -> 98.79
A29: 2. Kết quả thực hiện các thương hiệu trong 6 tháng đầu năm2026
A30: 1. Kết quả thực hiện các thương hiệu :
A31: ➢ SX 40x80 men Panson nung 1.5 lần:
A32: Kh/TH | B32: Thực Hiện | J32: Tỷ lệ % | L32: Ghi chú | N32: ok
B33: A1 | D33: A | F33: B | H33: Tổng A1+A+B
A34: Luxury | B34: =+T5.2026!B55+T6.2026!B34 -> 229150.4 | F34: =+T5.2026!F55+T6.2026!F34 -> 19508.8 | H34: =+B34+D34+F34 -> 248659.2
B35: =+B34/$H$34*100 -> 92.154402 | C35: =+C34/C56*100 -> #REF! | D35: =+D34/$H$34*100 -> 0 | E35: =+E34/E56*100 -> #REF! | F35: =+F34/$H$34*100 -> 7.8455975 | G35: =+G34/G56*100 -> #REF! | H35: =+H34/$H$34*100 -> 100 | I35: =+I34/I56*100 -> #REF! | J35: =+H34/$H$56*100 -> 33.606446
A36: Green Home | B36: =+T5.2026!B53+T6.2026!B36 -> 12139.2 | F36: =+T5.2026!F53+T6.2026!F36 -> 844.8 | H36: =+B36+D36+F36 -> 12984
B37: =+B36/$H$36*100 -> 93.49353 | C37: =+C36/C42*100 -> #DIV/0! | D37: =+D36/$H$36*100 -> 0 | E37: =+E36/E42*100 -> #DIV/0! | F37: =+F36/$H$36*100 -> 6.5064695 | G37: =+G36/G42*100 -> #DIV/0! | H37: =+H36/$H$36*100 -> 100 | I37: =+I36/I42*100 -> #DIV/0! | J37: =+H36/$H$56*100 -> 1.7547957
A38: Havira | B38: =+T5.2026!B67+T6.2026!B40 -> 27212.8 | F38: =+T5.2026!F67+T6.2026!F40 -> 1203.2 | H38: =+B38+D38+F38 -> 28416 | O38: =+T1.2026!H65+T4.2026!H67+T5.2026!H48 -> 595328 | P38: 2l 4080
B39: =+B38/$H$38*100 -> 95.765766 | C39: =+C38/C40*100 -> #DIV/0! | D39: =+D38/$H$38*100 -> 0 | E39: =+E38/E40*100 -> #DIV/0! | F39: =+F38/$H$38*100 -> 4.2342342 | G39: =+G38/G40*100 -> #DIV/0! | H39: =+H38/$H$38*100 -> 100 | I39: =+I38/I40*100 -> #DIV/0! | J39: =+H38/$H$56*100 -> 3.8404401 | O39: 739915.2 | P39: =+O38+O39 -> 1335243.2
A40: Top One | B40: =+T5.2026!B61+T6.2026!B48 -> 40243.2 | F40: =+T5.2026!F61+T6.2026!F48 -> 1872 | H40: =+B40+D40+F40 -> 42115.2
B41: =+B40/$H$40*100 -> 95.555049 | C41: =+C40/C42*100 -> #DIV/0! | D41: =+D40/$H$40*100 -> 0 | E41: =+E40/E42*100 -> #DIV/0! | F41: =+F40/$H$40*100 -> 4.444951 | G41: =+G40/G42*100 -> #DIV/0! | H41: =+H40/$H$40*100 -> 100 | I41: =+I40/I42*100 -> #DIV/0! | J41: =+H40/$H$56*100 -> 5.6918955
A42: Crovina | B42: =+T6.2026!B42 -> 35075.2 | F42: =+T6.2026!F42 -> 1182.4 | H42: =+B42+D42+F42 -> 36257.6
...

Sheet T7.2026
A1: CÔNG TY CỔ PHẦN GẠCH MEN PHƯƠNG NAM
A2: PHÂN XƯỞNG SẢN XUẤT DC2
A4: BÁO CÁO KẾT QUẢ SẢN XUẤT DÂY CHUYỀN SỐ 2 THÁNG 7 NĂM 2026
A6: I. Kết quả sản xuất tháng 07 năm 2026:
A7: I. Kết quả sản lượng – Chất lượng – Thu hồi ∑AB/ép :
A8: 1. Kết quả thực hiện Sản lượng – Chất lượng – Thu hồi ∑AB/ép
A9: Kích thước | C9: Sản Lượng Ép | D9: Sản lượng thu hồi | G9: Tổng (A1+A+B) | H9: Số ngày sx | I9: TB/ngày | J9: A/ép (%) | K9: C | L9: Hủy | M9: Dừng ép | O9: OK
A10: KH/TH | B10: ĐVT | D10: A1 | E10: A | F10: B | I10: m2 | K10: C/ép | L10: Hủy/ép | M10: phút/ngày
A11: KẾ HOẠCH 50*50 | B11: m2 | C11: =+G11*100/J12 -> 436170 | D11: =+$G$11*D12/100 -> 401799.8 | E11: =+$G$11*E12/100 -> 12823.398 | F11: =+$G$11*F12/100 -> 12823.398 | G11: =+I11*H11 -> 427446.6 | H11: 31 | I11: =21*0.5*1340*0.98 -> 13788.6 | K11: 4080
B12: % | D12: 94 | E12: 3 | F12: 3 | G12: 100 | J12: 98 | K12: 2 | M12: 100 | P12: =10.6*418800 -> 4439280
A13: THỰC HIỆN 50*50 | B13: m2 | C13: 442530 | D13: 434299.5 | E13: 0 | F13: 4056 | G13: =SUM(D13:F13) -> 438355.5 | H13: 31 | I13: =+G13/H13 -> 14140.5 | K13: 2746.3026 | L13: 3217.8553 | P13: =+P12/10.9 -> 407273.39
B14: % | D14: =+D13/G13*100 -> 99.074724 | E14: =+E13/G13*100 -> 0 | F14: =+F13/G13*100 -> 0.9252764 | G14: =SUM(D14:F14) -> 100 | J14: =+G13/C13*100 -> 99.056674 | K14: =100-J14 -> 0.94332588 | M14: 105.41935 | P14: =+P13*2390 -> 9.7338341e+08
A15: So sánh TH/KH 50*50 | B15: m2 | C15: =+C13-C11 -> 6360 | D15: =+D13-D11 -> 32499.696 | E15: =+(E13-E11) -> -12823.398 | F15: =+F13-F11 -> -8767.398 | G15: =SUM(D15:F15) -> 10908.9 | P15: =+P14/418800 -> 2324.2202
B16: % | D16: =+D14-D12 -> 5.0747236 | E16: =+E14-E12 -> -3 | F16: =+F14-F12 -> -2.0747236 | G16: 0 | N16: =97.5+1.29 -> 98.79
A17: 2. Kết quả thực hiện các thương hiệu trong tháng 7/2026
A18: 1. Kết quả thực hiện các thương hiệu :
A19: ➢ SX 50x50 men sân vườn sugar
A20: Kh/TH | B20: Thực Hiện | J20: Tỷ lệ % | L20: Ghi chú | O20: ok
B21: A1 | D21: A | F21: B | H21: Tổng A1+A+B
A22: Crovina | B22: 12798 | F22: 61.5 | H22: =+B22+D22+F22 -> 12859.5
B23: =+B22/$H$22*100 -> 99.521754 | C23: =+C22/C44*100 -> #REF! | D23: =+D22/$H$22*100 -> 0 | E23: =+E22/E44*100 -> #REF! | F23: =+F22/$H$22*100 -> 0.47824565 | G23: =+G22/G44*100 -> #REF! | H23: =+H22/$H$22*100 -> 100 | I23: =+I22/I44*100 -> #REF! | J23: =+H22/$H$44*100 -> 2.9352452
A24: Espana | B24: 6015 | F24: 46.5 | H24: =+B24+D24+F24 -> 6061.5
B25: =+B24/$H$24*100 -> 99.232863 | C25: =+C24/C32*100 -> #DIV/0! | D25: =+D24/$H$24*100 -> 0 | E25: =+E24/E32*100 -> #DIV/0! | F25: =+F24/$H$24*100 -> 0.76713685 | G25: =+G24/G32*100 -> #DIV/0! | H25: =+H24/$H$24*100 -> 100 | I25: =+I24/I32*100 -> #DIV/0! | J25: =+H24/$H$44*100 -> 1.3835677
A26: GreenHome | B26: 44280 | F26: 277.5 | H26: =+B26+D26+F26 -> 44557.5
B27: =+B26/$H$26*100 -> 99.377209 | C27: =+C26/#REF!*100 -> #REF! | D27: =+D26/$H$26*100 -> 0 | E27: =+E26/#REF!*100 -> #REF! | F27: =+F26/$H$26*100 -> 0.62279078 | G27: =+G26/#REF!*100 -> #REF! | H27: =+H26/$H$26*100 -> 100 | I27: =+I26/#REF!*100 -> #REF! | J27: =+H26/$H$44*100 -> 10.170472
A28: Trang Hoàng Phương | B28: 33048 | F28: 162 | H28: =+B28+D28+F28 -> 33210
B29: =+B28/$H$28*100 -> 99.512195 | C29: =+C28/C30*100 -> #DIV/0! | D29: =+D28/$H$28*100 -> 0 | E29: =+E28/E30*100 -> #DIV/0! | F29: =+F28/$H$28*100 -> 0.48780488 | G29: =+G28/G30*100 -> #DIV/0! | H29: =+H28/$H$28*100 -> 100 | I29: =+I28/I30*100 -> #DIV/0! | J29: =+H28/$H$44*100 -> 7.5803486
A30: Havira | B30: 41955 | F30: 484.5 | H30: =+B30+D30+F30 -> 42439.5
B31: =+B30/$H$30*100 -> 98.858375 | C31: =+C30/C32*100 -> #DIV/0! | D31: =+D30/$H$30*100 -> 0 | E31: =+E30/E32*100 -> #DIV/0! | F31: =+F30/$H$30*100 -> 1.1416251 | G31: =+G30/G32*100 -> #DIV/0! | H31: =+H30/$H$30*100 -> 100 | I31: =+I30/I32*100 -> #DIV/0! | J31: =+H30/$H$44*100 -> 9.6870282
A32: Karpo | B32: 10815 | F32: 25.5 | H32: =+B32+D32+F32 -> 10840.5
B33: =+B32/$H$32*100 -> 99.764771 | C33: =+C32/C44*100 -> #REF! | D33: =+D32/$H$32*100 -> 0 | E33: =+E32/E44*100 -> #REF! | F33: =+F32/$H$32*100 -> 0.235229 | G33: =+G32/G44*100 -> #REF! | H33: =+H32/$H$32*100 -> 100 | I33: =+I32/I44*100 -> #REF! | J33: =+H32/$H$44*100 -> 2.4743983
A34: Xanh tím | B34: 47070 | F34: 972 | H34: =+B34+D34+F34 -> 48042
B35: =+B34/$H$34*100 -> 97.97677 | C35: =+C34/C36*100 -> #DIV/0! | D35: =+D34/$H$30*100 -> 0 | E35: =+E34/E36*100 -> #DIV/0! | F35: =+F34/$H$34*100 -> 2.0232297 | G35: =+G34/G36*100 -> #DIV/0! | H35: =+H34/$H$34*100 -> 100 | I35: =+I34/I36*100 -> #DIV/0! | J35: =+H34/$H$44*100 -> 10.965827
A36: Padova | B36: 26700 | F36: 100.5 | H36: =+B36+D36+F36 -> 26800.5
B37: =+B36/$H$36*100 -> 99.625007 | C37: =+C36/#REF!*100 -> #REF! | D37: =+D36/$H$36*100 -> 0 | E37: =+E36/#REF!*100 -> #REF! | F37: =+F36/$H$36*100 -> 0.374993 | G37: =+G36/#REF!*100 -> #REF! | H37: =+H36/$H$36*100 -> 100 | I37: =+I36/#REF!*100 -> #REF! | J37: =+H36/$H$44*100 -> 6.1173482
A38: Luxury | B38: 166327.5 | F38: 1345.5 | H38: =+B38+D38+F38 -> 167673
B39: =+B38/$H$38*100 -> 99.197545 | C39: =+C38/C57*100 -> #DIV/0! | D39: =+D38/$H$38*100 -> 0 | E39: =+E38/E57*100 -> 0 | F39: =+F38/$H$38*100 -> 0.80245478 | G39: =+G38/G57*100 -> 0 | H39: =+H38/$H$38*100 -> 100 | I39: =+I38/I57*100 -> 0 | J39: =+H38/$H$44*100 -> 38.272201
A40: Top One | B40: 2992.5 | F40: 19.5 | H40: =+B40+D40+F40 -> 3012
B41: =+B40/$H$30*100 -> 7.0512141 | C41: =+C40/C42*100 -> #DIV/0! | D41: =+D40/$H$30*100 -> 0 | E41: =+E40/E42*100 -> #DIV/0! | F41: =+F40/$H$30*100 -> 0.045947761 | G41: =+G40/G42*100 -> #DIV/0! | H41: =+H40/$H$30*100 -> 7.0971618 | I41: =+I40/I42*100 -> #DIV/0! | J41: =+H40/$H$44*100 -> 0.68750407
A42: Vidona | B42: 42298.5 | F42: 312 | H42: =+B42+D42+F42 -> 42610.5
...

Sheet T8.2026
A1: CÔNG TY CỔ PHẦN GẠCH MEN PHƯƠNG NAM
A2: PHÂN XƯỞNG SẢN XUẤT DC2
A4: BÁO CÁO KẾT QUẢ SẢN XUẤT DÂY CHUYỀN SỐ 2 THÁNG 8 NĂM 2026
A6: I. Kết quả sản xuất tháng 08 năm 2026:
A7: I. Kết quả sản lượng – Chất lượng – Thu hồi ∑AB/ép :
A8: 1. Kết quả thực hiện Sản lượng – Chất lượng – Thu hồi ∑AB/ép
A9: Kích thước | C9: Sản Lượng Ép | D9: Sản lượng thu hồi | G9: Tổng (A1+A+B) | H9: Số ngày sx | I9: TB/ngày | J9: A/ép (%) | K9: C | L9: Hủy | M9: Dừng ép | O9: OK
A10: KH/TH | B10: ĐVT | D10: A1 | E10: A | F10: B | I10: m2 | K10: C/ép | L10: Hủy/ép | M10: phút/ngày
A11: KẾ HOẠCH 50*50 MEN MATT SUGAR | B11: m2 | C11: =+G11*100/J12 -> 56280 | D11: =+$G$11*D12/100 -> 51845.136 | E11: =+$G$11*E12/100 -> 0 | F11: =+$G$11*F12/100 -> 3309.264 | G11: =+I11*H11 -> 55154.4 | H11: 4 | I11: =21*0.5*1340*0.98 -> 13788.6 | K11: 1126
B12: % | D12: 94 | E12: 0 | F12: 6 | G12: 100 | J12: 98 | K12: 2 | M12: 100 | P12: =10.6*418800 -> 4439280
A13: THỰC HIỆN 50*50 MEN MATT SUGAR | B13: m2 | C13: =+G13*100/J14 -> 61898.994 | D13: 60264 | E13: 0 | F13: 1204.5 | G13: =+D13+F13 -> 61468.5 | H13: 4 | I13: =+G13/H13 -> 15367.125 | K13: 252 | L13: 175.5 | P13: =+P12/10.9 -> 407273.39 | Q13: =+C13+C19 -> 176497.94
B14: % | D14: =+D13/G13*100 -> 98.04046 | E14: =+E13/G13*100 -> 0 | F14: =+F13/G13*100 -> 1.9595403 | G14: =SUM(D14:F14) -> 100 | J14: =100-K14 -> 99.304522 | K14: =+(K13+L13)/G13*100 -> 0.69547817 | M14: 100 | P14: =+P13*2390 -> 9.7338341e+08
A15: So sánh TH/KH 50*50 MATT SUGAR | B15: m2 | C15: =+C13-C11 -> 5618.994 | D15: =+D13-D11 -> 8418.864 | E15: =+E13-E11 -> 0 | F15: =+F13-F11 -> -2104.764 | G15: =+G13-G11 -> 6314.1
B16: % | D16: =+D14-D12 -> 4.0404597 | E16: =+E14-E12 -> 0 | F16: =+F14-F12 -> -4.0404597 | N16: =97.5+1.29 -> 98.79
A17: KẾ HOẠCH 50*50 MEN BÓNG | B17: m2 | C17: =+G17*100/J18 -> 113137.23 | D17: =+$G$17*D18/100 -> 98174.832 | E17: =+E15-E13 -> 0 | F17: =+$G$17*F18/100 -> 12133.968 | G17: =+H17*I17 -> 110308.8 | H17: 8 | I17: =0.5*1340*21*0.98 -> 13788.6 | K17: 4596 | P17: =+P14/418800 -> 2324.2202
B18: % | D18: 89 | E18: =+E16-E14 -> 0 | F18: 11 | G18: 0 | J18: 97.5 | K18: 2.5 | M18: =+K18+J18 -> 100 | N18: =97.5+1.29 -> 98.79 | P18: =+G13+G19 -> 174246
A19: THỰC HIỆN 50*50 MEN BÓNG | B19: m2 | C19: =+G19*100/J20 -> 114598.95 | D19: 107878.5 | E19: =+E17-E15 -> 0 | F19: 4899 | G19: =+D19+F19 -> 112777.5 | H19: 8 | I19: =+G19/H19 -> 14097.188 | K19: 553.5 | L19: 1239
B20: % | D20: =+D19/$G$19*100 -> 95.656048 | E20: =+E18-E16 -> 0 | F20: =+F19/$G$19*100 -> 4.3439516 | G20: =+D20+E20+F20 -> 100 | J20: =100-K20 -> 98.410587 | K20: =+(K19+L19)/G19*100 -> 1.5894128 | M20: 48
A21: So sánh TH/KH 50*50 BÓNG | B21: m2 | C21: =+C19-C17 -> 1461.7196 | D21: =+D19-D17 -> 9703.668 | E21: =+E19-E17 -> 0 | F21: =+F19-F17 -> -7234.968 | G21: =+G19-G17 -> 2468.7
B22: % | D22: =+D20-D18 -> 6.6560484 | E22: =+E20-E18 -> 0 | F22: =+F20-F18 -> -6.6560484 | G22: 0 | N22: =97.5+1.29 -> 98.79
A23: KẾ HOẠCH 40*80 | B23: m2 | C23: =+G23*100/J24 -> 263692.8 | D23: =+G23*D24/100 -> 232577.05 | E23: =+E21-E19 -> 0 | F23: =+G23*F24/100 -> 25841.894 | G23: =+I23*H23 -> 258418.94 | H23: 18 | I23: =10.9*0.96*1400*0.98 -> 14356.608 | K23: 3809
B24: % | D24: 90 | E24: =+E22-E20 -> 0 | F24: 10 | G24: 100 | J24: 98 | K24: =100-J24 -> 2 | M24: 40
A25: THỰC HIỆN 40*80 | B25: m2 | C25: =+G25*100/J26 -> 273289.11 | D25: 252729.6 | E25: =+E23-E21 -> 0 | F25: 17681.6 | G25: =+F25+D25 -> 270411.2 | H25: 18 | I25: =+G25/H25 -> 15022.844 | K25: 1203.8 | L25: 1643.8
B26: % | D26: =+D25/G25*100 -> 93.461218 | E26: =+E24-E22 -> 0 | F26: =+F25/G25*100 -> 6.5387824 | G26: =SUM(D26:F26) -> 100 | J26: =100-K26 -> 98.946937 | K26: =+(K25+L25)/G25*100 -> 1.0530629 | M26: 13
A27: So sánh TH/KH 40*80 | B27: m2 | C27: =+C25-C23 -> 9596.3062 | D27: =+D25-D23 -> 20152.55 | E27: =+E25-E23 -> 0 | F27: =+F25-F23 -> -8160.2944 | G27: =+D27+F27 -> 11992.256
B28: % | D28: =+D26-D24 -> 3.4612176 | E28: =+E26-E20 -> 0 | F28: =+F26-F24 -> -3.4612176 | N28: =97.5+1.29 -> 98.79
A29: 2. Kết quả thực hiện các thương hiệu trong tháng 8/2026
A30: 1. Kết quả thực hiện các thương hiệu :
A31: ➢ SX 500x500 men Matt Sugar :
A32: Kh/TH | B32: Thực Hiện | J32: Tỷ lệ % | L32: Ghi chú | O32: OK
B33: A1 | D33: A | F33: B | H33: Tổng A1+A+B
A34: Green Home | B34: 4509 | F34: 774 | H34: =+B34+D34+F34 -> 5283
B35: =+B34/$H$34*100 -> 85.349233 | C35: =+C34/C42*100 -> #REF! | D35: =+D34/$H$34*100 -> 0 | E35: =+E34/E42*100 -> #REF! | F35: =+F34/$H$34*100 -> 14.650767 | G35: =+G34/G42*100 -> #REF! | H35: =+H34/$H$34*100 -> 100 | I35: =+I34/I42*100 -> #REF! | J35: =+H34/$H$42*100 -> 8.594646
A36: Havira | B36: 5017.5 | F36: 16.5 | H36: =+B36+D36+F36 -> 5034
B37: =+B36/$H$36*100 -> 99.672229 | C37: =+C36/#REF!*100 -> #REF! | D37: =+D36/$H$36*100 -> 0 | E37: =+E36/#REF!*100 -> #REF! | F37: =+F36/$H$36*100 -> 0.32777116 | G37: =+G36/#REF!*100 -> #REF! | H37: =+H36/$H$36*100 -> 100 | I37: =+I36/#REF!*100 -> #REF! | J37: =+H36/$H$42*100 -> 8.1895605
A38: Luxury | B38: 24255 | F38: 210 | H38: =+B38+D38+F38 -> 24465
B39: =+B38/$H$38*100 -> 99.141631 | C39: =+C38/#REF!*100 -> #REF! | D39: =+D38/$H$38*100 -> 0 | E39: =+E38/#REF!*100 -> #REF! | F39: =+F38/$H$38*100 -> 0.8583691 | G39: =+G38/#REF!*100 -> #REF! | H39: =+H38/H38*100 -> 100 | I39: =+I38/#REF!*100 -> #REF! | J39: =+H38/$H$42*100 -> 39.800874
A40: Xanh Tím | B40: 26482.5 | F40: 204 | H40: =+B40+D40+F40 -> 26686.5
B41: =+B40/$H$40*100 -> 99.235569 | C41: =+C40/#REF!*100 -> #REF! | D41: =+D40/$H$40*100 -> 0 | E41: =+E40/#REF!*100 -> #REF! | F41: =+F40/$H$40*100 -> 0.76443145 | G41: =+G40/#REF!*100 -> #REF! | H41: =+H40/$H$40*100 -> 100 | I41: =+I40/#REF!*100 -> #REF! | J41: =+H40/$H$42*100 -> 43.41492
A42: Tổng | B42: =+B34+B36+B38+B40 -> 60264 | C42: =+#REF!+#REF!+#REF!+#REF!+#REF!+#REF!+C34 -> #REF! | D42: =+D34+D36+D38+D40 -> 0 | E42: =+#REF!+#REF!+#REF!+#REF!+#REF!+#REF!+E34 -> #REF! | F42: =+F34+F36+F38+F40 -> 1204.5 | G42: =+#REF!+#REF!+#REF!+#REF!+#REF!+#REF!+G34 -> #REF! | H42: =+H34+H36+H38+H40 -> 61468.5 | I42: =+#REF!+#REF!+#REF!+#REF!+#REF!+#REF!+I34 -> #REF!
...
