Workbook
Name Slicer_Dây_chuyền: #N/A
Name Slicer_Dây_chuyền1: #N/A
Name Slicer_DC: #N/A
Name Slicer_DC1: #N/A
Name Slicer_Kích_thước: #N/A
Name Slicer_Kích_thước1: #N/A
Name Slicer_Kích_thước2: #N/A
Name Slicer_Kích_thước3: #N/A
Name Slicer_Men: #N/A
Name Slicer_Nguyên_liệu__vật_tư: #N/A
Name Slicer_Tên_than: #N/A
Name Slicer_Tháng: #N/A
Name Slicer_Tháng1: #N/A
Name Slicer_Tháng2: #N/A
Name Slicer_Tháng3: #N/A
Name Slicer_Thương_hiệu: #N/A
Name T1_Headers: 'T1.2025'!$A$137:$O$137
Name T2_Headers: 'T2.2025 '!$A$61:$P$61
Name T3_Headers: 'T3.2025 '!$A$112:$P$112
Name T4_Headers: 'T4.2025 '!$A$141:$P$141
Name T5_Headers: 'Form mẫu'!$A$206:$O$206
Name T5_Headers: 'T5.2025'!$A$196:$P$196
Name T6_Headers: 'T6.2025'!$A$200:$P$200

Sheet TH SX Năm 2025
B1: CÔNG TY CỔ PHẦN GẠCH MEN PHƯƠNG NAM
B2: Địa chỉ: Cụm CN VLXD Tân An, X. Tân An, H. Vĩnh Cửu, T. Đồng Nai
B3: Điện thoại: 0251 3684039 *** Email: gachmenphuongnam@gmail.com | R3: NHẬP SỐ LIỆU THEO THÁNG | AD3: NHẬP SỐ LIỆU THEO THÁNG
B5: BÁO CÁO KẾT QUẢ SẢN XUẤT 2 DÂY CHUYỀN NĂM 2025 | Q5: 30X60 (TH) | R5: MEN | S5: SL ÉP | T5: A1 | U5: A | V5: B | W5: Tổng A1-A-B | X5: Số ngày SX | Y5: TB/ Ngày | Z5: C | AA5: Huỷ/ ép | AB5: T/g dừng 2 ME | AD5: 30X60 (KH) | AE5: SL ép | AF5: A1 | AG5: A | AH5: B | AI5: Tổng A1-A-B | AJ5: Số ngày SX | AK5: TB/ Ngày | AL5: T/g dừng 2 ME
B6: I. Kết quả sản lượng - Chất lượng - thu hồi Tổng A1+A+B : | Q6: T1 | R6: PN | S6: ='T1.2025'!E10 -> 0 | T6: ='T1.2025'!F61 -> 0 | U6: ='T1.2025'!G61 -> 0 | V6: ='T1.2025'!H61 -> 0 | W6: =SUM(T6:V6) -> 0 | X6: ='T1.2025'!J10 -> 0 | Z6: ='T1.2025'!M10 -> 0 | AA6: ='T1.2025'!N10 -> 0 | AB6: ='T1.2025'!O10 -> 0 | AD6: T1 | AE6: ='T1.2025'!E8 -> 0 | AF6: ='T1.2025'!F8 -> 0 | AG6: ='T1.2025'!G8 -> 0 | AH6: ='T1.2025'!H8 -> 0 | AI6: =SUM(AF6:AH6) -> 0 | AJ6: ='T1.2025'!J8 -> 0 | AK6: ='T1.2025'!K8 -> 0 | AL6: ='T1.2025'!O8 -> 0
B7: 1. Dây chuyền số 1 | R7: PSG | T7: ='T1.2025'!F51 -> 0 | U7: ='T1.2025'!G51 -> 0 | V7: ='T1.2025'!H51 -> 0 | W7: =SUM(T7:V7) -> 0
R8: M | T8: ='T1.2025'!F71 -> 0 | U8: ='T1.2025'!G71 -> 0 | V8: ='T1.2025'!H71 -> 0 | W8: =SUM(T8:V8) -> 0
B9: Kích thước | D9: Sản Lượng ép | E9: Sản lượng thu hồi | H9: Tổng (A1+A+B) | I9: Số ngày SX | J9: TB/ngày | K9: A/ép (%) | L9: C | M9: Huỷ | N9: T/g dừng 2 ME | Q9: T2 | R9: PN | S9: ='T2.2025 '!E11 -> 107045 | T9: ='T2.2025 '!F57 -> 91149.12 | U9: ='T2.2025 '!G57 -> 5847.84 | V9: ='T2.2025 '!H57 -> 5804.64 | W9: ='T2.2025 '!I57 -> 102801.6 | X9: ='T2.2025 '!J11 -> 6.6 | Y9: ='T2.2025 '!K11 -> 15576 | Z9: ='T2.2025 '!M11 -> 649.44 | AA9: ='T2.2025 '!N11 -> 1362.1 | AB9: ='T2.2025 '!O11 -> 36 | AD9: T2 | AE9: ='T2.2025 '!E9 -> 94338.462 | AF9: ='T2.2025 '!F9 -> 81862.2 | AG9: ='T2.2025 '!G9 -> 5518.8 | AH9: ='T2.2025 '!H9 -> 4599 | AI9: =SUM(AF9:AH9) -> 91980 | AJ9: ='T2.2025 '!J9 -> 7 | AK9: =AI9/AJ9 -> 13140 | AL9: ='T2.2025 '!O9 -> 40
B10: KH/TH | C10: ĐVT | E10: A1 | F10: A | G10: B | J10: m2 | L10: C/ép | M10: Huỷ/ép | N10: Phút/ngày | R10: PSG | W10: =SUM(T10:V10) -> 0 | AI10: =SUM(AF10:AH10) -> 0
B11: KẾ HOẠCH 30x60 | C11: m2 | D11: =AE42 -> 1674275.8 | E11: =AF42 -> 1198573.2 | F11: =AG42 -> 80802.69 | G11: =AH42 -> 67335.575 | H11: =AI42 -> 1346711.5 | I11: =AJ42 -> 111.75 | J11: =AK42 -> 12051.11 | N11: =AL42 -> 40 | R11: M | W11: =SUM(T11:V11) -> 0 | AI11: =SUM(AF11:AH11) -> 0
C12: % | E12: 89 | F12: 6 | G12: 5 | H12: 100 | K12: 97.5 | L12: =100-K12 -> 2.5 | Q12: T3 | R12: PN | S12: ='T3.2025 '!E10 -> 496651 | T12: ='T3.2025 '!F53 -> 222084 | U12: ='T3.2025 '!G53 -> 7130.88 | V12: ='T3.2025 '!H53 -> 9993.6 | W12: =SUM(T12:V12) -> 239208.48 | X12: ='T3.2025 '!G80 -> 15.159073 | Y12: =+W12/X12 -> 15779.888 | Z12: ='T3.2025 '!M10 -> 1677.66 | AA12: ='T3.2025 '!N10 -> 2278.54 | AB12: ='T3.2025 '!O10 -> 25 | AD12: T3 | AE12: ='T3.2025 '!E8 -> 487415.38 | AF12: ='T3.2025 '!F8 -> 422954.7 | AG12: ='T3.2025 '!G8 -> 28513.8 | AH12: ='T3.2025 '!H8 -> 23761.5 | AI12: =SUM(AF12:AH12) -> 475230 | AJ12: ='T3.2025 '!J8 -> 31 | AK12: =AI12/AJ12 -> 15330 | AL12: ='T3.2025 '!O9 -> 40
B13: THỰC HIỆN 30x60 | C13: m2 | D13: =S42 -> 1733166 | E13: =T42 -> 1562421.6 | F13: =U42 -> 50064.48 | G13: =V42 -> 90155.52 | H13: =W42 -> 1702641.6 | I13: =X42 -> 111.95001 | J13: =Y42 -> 15208.946 | L13: =Z42 -> 7357.02 | M13: =AA42 -> 7800.8 | N13: =AB42 -> 26 | R13: PSG | T13: ='T3.2025 '!F63 -> 231760.8 | U13: ='T3.2025 '!G63 -> 2617.92 | V13: ='T3.2025 '!H63 -> 15589.44 | W13: =SUM(T13:V13) -> 249968.16 | X13: ='T3.2025 '!G81 -> 15.840933 | Y13: =+W13/X13 -> 15779.888 | AI13: =SUM(AF13:AH13) -> 0
C14: % | E14: =E13/H13*100 -> 91.764562 | F14: =F13/H13*100 -> 2.9404004 | G14: =G13/H13*100 -> 5.295038 | H14: =SUM(E14:G14) -> 100 | K14: =H13/D13*100 -> 98.238807 | L14: =100-K14 -> 1.7611931 | R14: M | W14: =SUM(T14:V14) -> 0 | AI14: =SUM(AF14:AH14) -> 0
B15: So sánh TH/KH | C15: m2 | D15: =+D13-D11 -> 58890.215 | E15: =+E13-E11 -> 363848.36 | F15: =+F13-F11 -> -30738.21 | G15: =+G13-G11 -> 22819.945 | H15: =+H13-H11 -> 355930.1 | N15: =N11-N13 -> 14 | Q15: T4 | R15: PN | S15: ='T4.2025 '!E11 -> 446786 | T15: ='T4.2025 '!F62 -> 363058.56 | U15: ='T4.2025 '!G62 -> 11676.96 | V15: ='T4.2025 '!H62 -> 17922.24 | W15: =SUM(T15:V15) -> 392657.76 | X15: ='T4.2025 '!G89 -> 26.706703 | Y15: =+W15/X15 -> 14702.592 | Z15: ='T4.2025 '!M11 -> 1512 | AA15: ='T4.2025 '!N11 -> 1572.48 | AB15: ='T4.2025 '!O11 -> 24 | AD15: T4 | AE15: ='T4.2025 '!E9 -> 436836.73 | AF15: ='T4.2025 '!F9 -> 381009 | AG15: ='T4.2025 '!G9 -> 25686 | AH15: ='T4.2025 '!H9 -> 21405 | AI15: =SUM(AF15:AH15) -> 428100 | AJ15: ='T4.2025 '!J9 -> 30 | AK15: =AI15/AJ15 -> 14270 | AL15: 40
C16: % | D16: =+D14-D12 -> 0 | E16: =+E14-E12 -> 2.7645616 | F16: =+F14-F12 -> -3.0595996 | G16: =+G14-G12 -> 0.29503802 | R16: PSG | T16: ='T4.2025 '!F72 -> 44935.2 | U16: ='T4.2025 '!G72 -> 853.92 | V16: ='T4.2025 '!H72 -> 2630.88 | W16: =SUM(T16:V16) -> 48420 | X16: ='T4.2025 '!G90 -> 3.2932969 | Y16: =+W16/X16 -> 14702.592 | AI16: =SUM(AF16:AH16) -> 0
R17: M | W17: =SUM(T17:V17) -> 0 | AI17: =SUM(AF17:AH17) -> 0
Q18: T5 | R18: PN | S18: ='T5.2025'!E11 -> 366803 | T18: ='T5.2025'!F68 -> 250378.56 | U18: ='T5.2025'!G68 -> 9181.44 | V18: ='T5.2025'!H68 -> 13044.96 | W18: =SUM(T18:V18) -> 272604.96 | X18: ='T5.2025'!G95 -> 18.69023 | Y18: =+W18/X18 -> 14585.425 | Z18: ='T5.2025'!M11 -> 1689.12 | AA18: ='T5.2025'!N11 -> 1297.44 | AB18: ='T5.2025'!O11 -> 26 | AD18: T5 | AE18: ='T5.2025'!E9 -> 358470.92 | AF18: ='T5.2025'!F9 -> 312658.34 | AG18: ='T5.2025'!G9 -> 21078.09 | AH18: ='T5.2025'!H9 -> 17565.075 | AI18: =SUM(AF18:AH18) -> 351301.5 | AJ18: ='T5.2025'!J9 -> 24.75 | AK18: =AI18/AJ18 -> 14194 | AL18: ='T5.2025'!O9 -> 40
R19: PSG | T19: ='T5.2025'!F78 -> 30405.6 | U19: ='T5.2025'!G78 -> 172.8 | V19: ='T5.2025'!H78 -> 3666.24 | W19: =SUM(T19:V19) -> 34244.64 | X19: ='T5.2025'!G96 -> 2.3478671 | Y19: =+W19/X19 -> 14585.425 | AI19: =SUM(AF19:AH19) -> 0
R20: M | T20: ='T5.2025'!F88 -> 51896.16 | U20: ='T5.2025'!G88 -> 158.4 | V20: ='T5.2025'!H88 -> 2085.12 | W20: =SUM(T20:V20) -> 54139.68 | X20: ='T5.2025'!G97 -> 3.7119027 | Y20: =+W20/X20 -> 14585.425 | AI20: =SUM(AF20:AH20) -> 0
B21: 2. Dây chuyền số 2: | Q21: T6 | R21: PN | S21: ='T6.2025'!E11 -> 315881 | T21: ='T6.2025'!F11 -> 276753.6 | U21: ='T6.2025'!G11 -> 12424.32 | V21: ='T6.2025'!H11 -> 19418.4 | W21: =SUM(T21:V21) -> 308596.32 | X21: ='T6.2025'!G97 -> 19.6 | Y21: =+W21/X21 -> 15744.71 | Z21: ='T6.2025'!M11 -> 1828.8 | AA21: ='T6.2025'!N11 -> 1290.24 | AB21: ='T6.2025'!O11 -> 19 | AD21: T6 | AE21: ='T6.2025'!E9 -> 297214.29 | AF21: ='T6.2025'!F9 -> 89 | AG21: ='T6.2025'!G9 -> 6 | AH21: ='T6.2025'!H9 -> 5 | AI21: =SUM(AF21:AH21) -> 100 | AJ21: ='T6.2025'!J9 -> 19 | AK21: =AI21/AJ21 -> 5.2631579 | AL21: 40
R22: PSG | W22: =SUM(T22:V22) -> 0 | AI22: =SUM(AF22:AH22) -> 0
B23: Kích thước | D23: Sản Lượng Ép | E23: Sản lượng thu hồi | H23: Tổng (A1+A+B) | I23: Số ngày SX | J23: TB/ngày | K23: A/ép (%) | L23: C | M23: Hủy | N23: T/g dừng 2 ME | R23: M | W23: =SUM(T23:V23) -> 0 | AI23: =SUM(AF23:AH23) -> 0
B24: KH/TH | C24: ĐVT | E24: A1 | F24: A | G24: B | J24: m2 | L24: C/ép | M24: Hủy/ép | N24: Phút/ngày | Q24: T7 | R24: PN | W24: =SUM(T24:V24) -> 0 | AD24: T7 | AI24: =SUM(AF24:AH24) -> 0
B25: KẾ HOẠCH 40*80 | C25: m2 | D25: =AE121 -> 1058326.5 | E25: =AF121 -> 550429.4 | F25: =AG121 -> 49476.8 | G25: =AH121 -> 18553.8 | H25: =AI121 -> 618460 | I25: =AJ121 -> 74.6 | J25: =AK121 -> 8290.3485 | N25: =AL121 -> 40 | R25: PSG | W25: =SUM(T25:V25) -> 0 | AI25: =SUM(AF25:AH25) -> 0
C26: % | E26: 89 | F26: =F25/H25*100 -> 8 | G26: =G25/H25*100 -> 3 | H26: =SUM(E26:G26) -> 100 | K26: 98 | L26: =100-K26 -> 2 | R26: M | W26: =SUM(T26:V26) -> 0 | AI26: =SUM(AF26:AH26) -> 0
B27: THỰC HIỆN 40*80 | C27: m2 | D27: =S121 -> 1085392 | E27: =T121 -> 985953.92 | F27: =U121 -> 184.32 | G27: =V121 -> 76234.88 | H27: =W121 -> 1062373.1 | I27: =X121 -> 74.95 | J27: =Y121 -> 14174.425 | L27: =Z121 -> 5328 | M27: =AA121 -> 7905.6 | N27: =AB121 -> 22 | Q27: T8 | R27: PN | W27: =SUM(T27:V27) -> 0 | AD27: T8 | AI27: =SUM(AF27:AH27) -> 0
C28: % | E28: =+E27/H27*100 -> 92.806746 | F28: =+F27/H27*100 -> 0.017349837 | G28: =+G27/H27*100 -> 7.1759045 | H28: =SUM(E28:G28) -> 100 | K28: =H27/D27*100 -> 97.87921 | L28: =100-K28 -> 2.1207895 | R28: PSG | W28: =SUM(T28:V28) -> 0 | AI28: =SUM(AF28:AH28) -> 0
B29: KẾ HOẠCH 50*50 SUGAR | C29: m2 | D29: =AE75 -> 488254.56 | E29: =AF75 -> 446436.82 | F29: =AG75 -> 17544.308 | G29: =AH75 -> 12822.829 | H29: =AI75 -> 476803.96 | I29: =AJ75 -> 38.15 | J29: =AK75 -> 37314.08 | N29: =AL75 -> 100 | R29: M | W29: =SUM(T29:V29) -> 0 | AI29: =SUM(AF29:AH29) -> 0
C30: % | E30: 92 | F30: 5 | G30: 3 | H30: =SUM(E30:G30) -> 100 | K30: 97.5 | L30: =100-K30 -> 2.5 | Q30: T9 | R30: PN | W30: =SUM(T30:V30) -> 0 | AD30: T9 | AI30: =SUM(AF30:AH30) -> 0
B31: THỰC HIỆN 50*50 SUGAR | C31: m2 | D31: =S75 -> 497019 | E31: =T75 -> 420913.5 | F31: =U75 -> 0 | G31: =V75 -> 5400 | H31: =W75 -> 426313.5 | I31: =X75 -> 33.214597 | J31: =Y75 -> 38486.875 | L31: =Z75 -> 1851 | M31: =AA75 -> 2887 | N31: =AB75 -> 146 | R31: PSG | W31: =SUM(T31:V31) -> 0 | AI31: =SUM(AF31:AH31) -> 0
C32: % | E32: =E31/H31*100 -> 98.733327 | F32: =+F31/H31*100 -> 0 | G32: =+G31/H31*100 -> 1.2666735 | H32: =SUM(E32:G32) -> 100 | K32: =H31/D31*100 -> 85.774085 | L32: =100-K32 -> 14.225915 | R32: M | W32: =SUM(T32:V32) -> 0 | AI32: =SUM(AF32:AH32) -> 0
B33: KẾ HOẠCH 50*50 BÓNG | C33: m2 | D33: =AE76 -> 23338.462 | E33: =AF76 -> 20934.6 | F33: =AG76 -> 1137.75 | G33: =AH76 -> 682.65 | H33: =AI76 -> 22755 | I33: =AJ76 -> 1.85 | J33: =AK76 -> 12300 | N33: 100 | Q33: T10 | R33: PN | W33: =SUM(T33:V33) -> 0 | AD33: T10 | AI33: =SUM(AF33:AH33) -> 0
C34: % | E34: 92 | F34: 5 | G34: 3 | H34: =SUM(E34:G34) -> 100 | K34: 97.5 | L34: =100-K34 -> 2.5 | R34: PSG | W34: =SUM(T34:V34) -> 0 | AI34: =SUM(AF34:AH34) -> 0
B35: THỰC HIỆN 50*50 BÓNG | C35: m2 | D35: =S76 -> 23615 | E35: =T76 -> 79593 | F35: =U76 -> 0 | G35: =V76 -> 8863.5 | H35: =W76 -> 88456.5 | I35: =X76 -> 6.7854032 | J35: =Y76 -> 25817.5 | L35: =Z76 -> 0 | M35: =AA76 -> 0 | N35: =AB76 -> 146 | R35: M | W35: =SUM(T35:V35) -> 0 | AI35: =SUM(AF35:AH35) -> 0
C36: % | E36: =+E35/H35*100 -> 89.979821 | F36: =+F35/H35*100 -> 0 | G36: =+G35/H35*100 -> 10.020179 | H36: =SUM(E36:G36) -> 100 | K36: =H35/D35*100 -> 374.5776 | L36: =100-K36 -> -274.5776 | Q36: T11 | R36: PN | W36: =SUM(T36:V36) -> 0 | AD36: T11 | AI36: =SUM(AF36:AH36) -> 0
B37: KẾ HOẠCH 60*60 BÓNG | C37: m2 | D37: =AE105 -> 117312.82 | E37: =AF105 -> 101798.2 | F37: =AG105 -> 5719 | G37: =AH105 -> 6862.8 | H37: =AI105 -> 114380 | I37: =AJ105 -> 9.5 | J37: =AK105 -> 12040 | N37: 100 | R37: PSG | W37: =SUM(T37:V37) -> 0 | AI37: =SUM(AF37:AH37) -> 0
C38: % | E38: 92 | F38: 5 | G38: 3 | H38: =SUM(E38:G38) -> 100 | K38: 97.5 | L38: =100-K38 -> 2.5 | R38: M | W38: =SUM(T38:V38) -> 0 | AI38: =SUM(AF38:AH38) -> 0
B39: THỰC HIỆN 60*60 BÓNG | C39: m2 | D39: =S105 -> 119675 | E39: =T105 -> 93891.6 | F39: =U105 -> 0 | G39: =V105 -> 5347.08 | H39: =W105 -> 99238.68 | I39: =X105 -> 8.0883283 | J39: =Y105 -> 12269.368 | L39: =Z105 -> 712.8 | M39: =AA105 -> 758.52 | N39: =AB105 -> 230 | Q39: T12 | R39: PN | W39: =SUM(T39:V39) -> 0 | AD39: T12 | AI39: =SUM(AF39:AH39) -> 0
C40: % | E40: =+E39/H39*100 -> 94.611899 | F40: =+F39/H39*100 -> 0 | G40: =+G39/H39*100 -> 5.3881007 | H40: =SUM(E40:G40) -> 100 | K40: =H39/D39*100 -> 82.923484 | L40: =100-K40 -> 17.076516 | R40: PSG | W40: =SUM(T40:V40) -> 0 | AI40: =SUM(AF40:AH40) -> 0
B41: KẾ HOẠCH 60*60 MATT | C41: m2 | D41: =AE83 -> 0 | E41: =AF83 -> 0 | F41: =AG83 -> 0 | G41: =AH83 -> 0 | H41: =AI83 -> 0 | I41: =AJ83 -> 0 | J41: =AK83 -> 0 | N41: 100 | R41: M | W41: =SUM(T41:V41) -> 0 | AI41: =SUM(AF41:AH41) -> 0
...

Sheet TH SX 6 tháng đầu năm 2025
B1: CÔNG TY CỔ PHẦN GẠCH MEN PHƯƠNG NAM
B2: Địa chỉ: Cụm CN VLXD Tân An, X. Tân An, H. Vĩnh Cửu, T. Đồng Nai
B3: Điện thoại: 0251 3684039 *** Email: gachmenphuongnam@gmail.com | R3: NHẬP SỐ LIỆU THEO THÁNG | AD3: NHẬP SỐ LIỆU THEO THÁNG
B5: BÁO CÁO KẾT QUẢ SẢN XUẤT 2 DÂY CHUYỀN 06 THÁNG ĐẦU NĂM 2025 | Q5: 30X60 (TH) | R5: MEN | S5: SL ÉP | T5: A1 | U5: A | V5: B | W5: Tổng A1-A-B | X5: Số ngày SX | Y5: TB/ Ngày | Z5: C | AA5: Huỷ/ ép | AB5: T/g dừng 2 ME | AD5: 30X60 (KH) | AE5: SL ép | AF5: A1 | AG5: A | AH5: B | AI5: Tổng A1-A-B | AJ5: Số ngày SX | AK5: TB/ Ngày | AL5: T/g dừng 2 ME
B6: I. Kết quả sản lượng - Chất lượng - thu hồi Tổng A1+A+B : | Q6: T1 | R6: PN | S6: ='T1.2025'!E10 -> 0 | T6: ='T1.2025'!F61 -> 0 | U6: ='T1.2025'!G61 -> 0 | V6: ='T1.2025'!H61 -> 0 | W6: =SUM(T6:V6) -> 0 | X6: ='T1.2025'!J10 -> 0 | Z6: ='T1.2025'!M10 -> 0 | AA6: ='T1.2025'!N10 -> 0 | AB6: ='T1.2025'!O10 -> 0 | AD6: T1 | AE6: ='T1.2025'!E8 -> 0 | AF6: ='T1.2025'!F8 -> 0 | AG6: ='T1.2025'!G8 -> 0 | AH6: ='T1.2025'!H8 -> 0 | AI6: =SUM(AF6:AH6) -> 0 | AJ6: ='T1.2025'!J8 -> 0 | AK6: ='T1.2025'!K8 -> 0 | AL6: ='T1.2025'!O8 -> 0
B7: 1. Dây chuyền số 1 | R7: PSG | T7: ='T1.2025'!F51 -> 0 | U7: ='T1.2025'!G51 -> 0 | V7: ='T1.2025'!H51 -> 0 | W7: =SUM(T7:V7) -> 0
R8: M | T8: ='T1.2025'!F71 -> 0 | U8: ='T1.2025'!G71 -> 0 | V8: ='T1.2025'!H71 -> 0 | W8: =SUM(T8:V8) -> 0
B9: Kích thước | D9: Sản Lượng ép | E9: Sản lượng thu hồi | H9: Tổng (A1+A+B) | I9: Số ngày SX | J9: TB/ngày | K9: A/ép (%) | L9: C | M9: Huỷ | N9: T/g dừng 2 ME | Q9: T2 | R9: PN | S9: ='T2.2025 '!E11 -> 107045 | T9: ='T2.2025 '!F57 -> 91149.12 | U9: ='T2.2025 '!G57 -> 5847.84 | V9: ='T2.2025 '!H57 -> 5804.64 | W9: ='T2.2025 '!I57 -> 102801.6 | X9: ='T2.2025 '!J11 -> 6.6 | Y9: ='T2.2025 '!K11 -> 15576 | Z9: ='T2.2025 '!M11 -> 649.44 | AA9: ='T2.2025 '!N11 -> 1362.1 | AB9: ='T2.2025 '!O11 -> 36 | AD9: T2 | AE9: ='T2.2025 '!E9 -> 94338.462 | AF9: ='T2.2025 '!F9 -> 81862.2 | AG9: ='T2.2025 '!G9 -> 5518.8 | AH9: ='T2.2025 '!H9 -> 4599 | AI9: =SUM(AF9:AH9) -> 91980 | AJ9: ='T2.2025 '!J9 -> 7 | AK9: =AI9/AJ9 -> 13140 | AL9: ='T2.2025 '!O9 -> 40
B10: KH/TH | C10: ĐVT | E10: A1 | F10: A | G10: B | J10: m2 | L10: C/ép | M10: Huỷ/ép | N10: Phút/ ngày | R10: PSG | W10: =SUM(T10:V10) -> 0 | AI10: =SUM(AF10:AH10) -> 0
B11: KẾ HOẠCH 30x60 | C11: m2 | D11: =AE46 -> 1674275.8 | E11: =AF46 -> 1198573.2 | F11: =AG46 -> 80802.69 | G11: =AH46 -> 67335.575 | H11: =AI46 -> 1346711.5 | I11: =AJ46 -> 111.75 | J11: =AK46 -> 12051.11 | N11: =AL46 -> 40 | R11: M | W11: =SUM(T11:V11) -> 0 | AI11: =SUM(AF11:AH11) -> 0
C12: % | E12: 89 | F12: 6 | G12: 5 | H12: 100 | K12: 97.5 | L12: =100-K12 -> 2.5 | Q12: T3 | R12: PN | S12: ='T3.2025 '!E10 -> 496651 | T12: ='T3.2025 '!F53 -> 222084 | U12: ='T3.2025 '!G53 -> 7130.88 | V12: ='T3.2025 '!H53 -> 9993.6 | W12: =SUM(T12:V12) -> 239208.48 | X12: ='T3.2025 '!G80 -> 15.159073 | Y12: =+W12/X12 -> 15779.888 | Z12: ='T3.2025 '!M10 -> 1677.66 | AA12: ='T3.2025 '!N10 -> 2278.54 | AB12: ='T3.2025 '!O10 -> 25 | AD12: T3 | AE12: ='T3.2025 '!E8 -> 487415.38 | AF12: ='T3.2025 '!F8 -> 422954.7 | AG12: ='T3.2025 '!G8 -> 28513.8 | AH12: ='T3.2025 '!H8 -> 23761.5 | AI12: =SUM(AF12:AH12) -> 475230 | AJ12: ='T3.2025 '!J8 -> 31 | AK12: =AI12/AJ12 -> 15330 | AL12: ='T3.2025 '!O9 -> 40
B13: THỰC HIỆN 30x60 | C13: m2 | D13: =S46 -> 1733166 | E13: =T46 -> 1562421.6 | F13: =U46 -> 50064.48 | G13: =V46 -> 90155.52 | H13: =W46 -> 1702641.6 | I13: =X46 -> 111.95001 | J13: =Y46 -> 15208.946 | L13: =Z46 -> 7357.02 | M13: =AA46 -> 7800.8 | N13: =AB46 -> 26 | R13: PSG | T13: ='T3.2025 '!F63 -> 231760.8 | U13: ='T3.2025 '!G63 -> 2617.92 | V13: ='T3.2025 '!H63 -> 15589.44 | W13: =SUM(T13:V13) -> 249968.16 | X13: ='T3.2025 '!G81 -> 15.840933 | Y13: =+W13/X13 -> 15779.888 | AI13: =SUM(AF13:AH13) -> 0
C14: % | E14: =E13/H13*100 -> 91.764562 | F14: =F13/H13*100 -> 2.9404004 | G14: =G13/H13*100 -> 5.295038 | H14: =SUM(E14:G14) -> 100 | K14: =H13/D13*100 -> 98.238807 | L14: =100-K14 -> 1.7611931 | R14: M | W14: =SUM(T14:V14) -> 0 | AI14: =SUM(AF14:AH14) -> 0
B15: So sánh TH/KH | C15: m2 | D15: =+D13-D11 -> 58890.215 | E15: =+E13-E11 -> 363848.36 | F15: =+F13-F11 -> -30738.21 | G15: =+G13-G11 -> 22819.945 | H15: =+H13-H11 -> 355930.1 | N15: =N11-N13 -> 14 | Q15: T4 | R15: PN | S15: ='T4.2025 '!E11 -> 446786 | T15: ='T4.2025 '!F62 -> 363058.56 | U15: ='T4.2025 '!G62 -> 11676.96 | V15: ='T4.2025 '!H62 -> 17922.24 | W15: =SUM(T15:V15) -> 392657.76 | X15: ='T4.2025 '!G89 -> 26.706703 | Y15: =+W15/X15 -> 14702.592 | Z15: ='T4.2025 '!M11 -> 1512 | AA15: ='T4.2025 '!N11 -> 1572.48 | AB15: ='T4.2025 '!O11 -> 24 | AD15: T4 | AE15: ='T4.2025 '!E9 -> 436836.73 | AF15: ='T4.2025 '!F9 -> 381009 | AG15: ='T4.2025 '!G9 -> 25686 | AH15: ='T4.2025 '!H9 -> 21405 | AI15: =SUM(AF15:AH15) -> 428100 | AJ15: ='T4.2025 '!J9 -> 30 | AK15: =AI15/AJ15 -> 14270 | AL15: 40
C16: % | D16: =+D14-D12 -> 0 | E16: =+E14-E12 -> 2.7645616 | F16: =+F14-F12 -> -3.0595996 | G16: =+G14-G12 -> 0.29503802 | R16: PSG | T16: ='T4.2025 '!F72 -> 44935.2 | U16: ='T4.2025 '!G72 -> 853.92 | V16: ='T4.2025 '!H72 -> 2630.88 | W16: =SUM(T16:V16) -> 48420 | X16: ='T4.2025 '!G90 -> 3.2932969 | Y16: =+W16/X16 -> 14702.592 | AI16: =SUM(AF16:AH16) -> 0
R17: M | W17: =SUM(T17:V17) -> 0 | AI17: =SUM(AF17:AH17) -> 0
Q18: T5 | R18: PN | S18: ='T5.2025'!E11 -> 366803 | T18: ='T5.2025'!F68 -> 250378.56 | U18: ='T5.2025'!G68 -> 9181.44 | V18: ='T5.2025'!H68 -> 13044.96 | W18: =SUM(T18:V18) -> 272604.96 | X18: ='T5.2025'!G95 -> 18.69023 | Y18: =+W18/X18 -> 14585.425 | Z18: ='T5.2025'!M11 -> 1689.12 | AA18: ='T5.2025'!N11 -> 1297.44 | AB18: ='T5.2025'!O11 -> 26 | AD18: T5 | AE18: ='T5.2025'!E9 -> 358470.92 | AF18: ='T5.2025'!F9 -> 312658.34 | AG18: ='T5.2025'!G9 -> 21078.09 | AH18: ='T5.2025'!H9 -> 17565.075 | AI18: =SUM(AF18:AH18) -> 351301.5 | AJ18: ='T5.2025'!J9 -> 24.75 | AK18: =AI18/AJ18 -> 14194 | AL18: ='T5.2025'!O9 -> 40
R19: PSG | T19: ='T5.2025'!F78 -> 30405.6 | U19: ='T5.2025'!G78 -> 172.8 | V19: ='T5.2025'!H78 -> 3666.24 | W19: =SUM(T19:V19) -> 34244.64 | X19: ='T5.2025'!G96 -> 2.3478671 | Y19: =+W19/X19 -> 14585.425 | AI19: =SUM(AF19:AH19) -> 0
R20: M | T20: ='T5.2025'!F88 -> 51896.16 | U20: ='T5.2025'!G88 -> 158.4 | V20: ='T5.2025'!H88 -> 2085.12 | W20: =SUM(T20:V20) -> 54139.68 | X20: ='T5.2025'!G97 -> 3.7119027 | Y20: =+W20/X20 -> 14585.425 | AI20: =SUM(AF20:AH20) -> 0
B21: 2. Dây chuyền số 2: | Q21: T6 | R21: PN | S21: ='T6.2025'!E11 -> 315881 | T21: ='T6.2025'!F11 -> 276753.6 | U21: ='T6.2025'!G11 -> 12424.32 | V21: ='T6.2025'!H11 -> 19418.4 | W21: =SUM(T21:V21) -> 308596.32 | X21: ='T6.2025'!G97 -> 19.6 | Y21: =+W21/X21 -> 15744.71 | Z21: ='T6.2025'!M11 -> 1828.8 | AA21: ='T6.2025'!N11 -> 1290.24 | AB21: ='T6.2025'!O11 -> 19 | AD21: T6 | AE21: ='T6.2025'!E9 -> 297214.29 | AF21: ='T6.2025'!F9 -> 89 | AG21: ='T6.2025'!G9 -> 6 | AH21: ='T6.2025'!H9 -> 5 | AI21: =SUM(AF21:AH21) -> 100 | AJ21: ='T6.2025'!J9 -> 19 | AK21: =AI21/AJ21 -> 5.2631579 | AL21: 40
R22: PSG | W22: =SUM(T22:V22) -> 0 | AI22: =SUM(AF22:AH22) -> 0
B23: Kích thước | D23: Sản Lượng Ép | E23: Sản lượng thu hồi | H23: Tổng (A1+A+B) | I23: Số ngày SX | J23: TB/ngày | K23: A/ép (%) | L23: C | M23: Hủy | N23: T/g dừng 2 ME | R23: M | W23: =SUM(T23:V23) -> 0 | AI23: =SUM(AF23:AH23) -> 0
B24: KH/TH | C24: ĐVT | E24: A1 | F24: A | G24: B | J24: m2 | L24: C/ép | M24: Hủy/ép | N24: Phút/ ngày | Q24: T7 | R24: PN | W24: =SUM(T24:V24) -> 0 | AD24: T7 | AI24: =SUM(AF24:AH24) -> 0
B25: KẾ HOẠCH 40*80 | C25: m2 | D25: =AE137 -> 1058326.5 | E25: =AF137 -> 550429.4 | F25: =AG137 -> 49476.8 | G25: =AH137 -> 18553.8 | H25: =AI137 -> 618460 | I25: =AJ137 -> 74.6 | J25: =AK137 -> 8290.3485 | N25: =AL137 -> 40 | R25: PSG | W25: =SUM(T25:V25) -> 0 | AI25: =SUM(AF25:AH25) -> 0
C26: % | E26: 89 | F26: =F25/H25*100 -> 8 | G26: =G25/H25*100 -> 3 | H26: =SUM(E26:G26) -> 100 | K26: 97.5 | L26: =100-K26 -> 2.5 | R26: M | W26: =SUM(T26:V26) -> 0 | AI26: =SUM(AF26:AH26) -> 0
B27: THỰC HIỆN 40*80 | C27: m2 | D27: =S137 -> 1085392 | E27: =T137 -> 985953.92 | F27: =U137 -> 184.32 | G27: =V137 -> 76234.88 | H27: =W137 -> 1062373.1 | I27: =X137 -> 74.95 | J27: =Y137 -> 14174.425 | L27: =Z137 -> 5328 | M27: =AA137 -> 7905.6 | N27: =AB137 -> 22 | Q27: T8 | R27: PN | W27: =SUM(T27:V27) -> 0 | AD27: T8 | AI27: =SUM(AF27:AH27) -> 0
C28: % | E28: =+E27/H27*100 -> 92.806746 | F28: =+F27/H27*100 -> 0.017349837 | G28: =+G27/H27*100 -> 7.1759045 | H28: =SUM(E28:G28) -> 100 | K28: =H27/D27*100 -> 97.87921 | L28: =100-K28 -> 2.1207895 | R28: PSG | W28: =SUM(T28:V28) -> 0 | AI28: =SUM(AF28:AH28) -> 0
B29: KẾ HOẠCH 50*50 SUGAR | C29: m2 | D29: =AE91 -> 488254.56 | E29: =AF91 -> 446436.82 | F29: =AG91 -> 17544.308 | G29: =AH91 -> 12822.829 | H29: =AI91 -> 476803.96 | I29: =AJ91 -> 38.15 | J29: =AK91 -> 12500.138 | N29: =AL91 -> 100 | R29: M | W29: =SUM(T29:V29) -> 0 | AI29: =SUM(AF29:AH29) -> 0
C30: % | E30: 92 | F30: 5 | G30: 3 | H30: =SUM(E30:G30) -> 100 | K30: 97.5 | L30: =100-K30 -> 2.5 | Q30: T9 | R30: PN | W30: =SUM(T30:V30) -> 0 | AD30: T9 | AI30: =SUM(AF30:AH30) -> 0
B31: THỰC HIỆN 50*50 SUGAR | C31: m2 | D31: =S91 -> 497019 | E31: =T91 -> 420913.5 | F31: =U91 -> 0 | G31: =V91 -> 5400 | H31: =W91 -> 426313.5 | I31: =X91 -> 33.214597 | J31: =Y91 -> #DIV/0! | L31: =Z91 -> 1851 | M31: =AA91 -> 2887 | N31: =AB91 -> 146 | R31: PSG | W31: =SUM(T31:V31) -> 0 | AI31: =SUM(AF31:AH31) -> 0
C32: % | E32: =E31/H31*100 -> 98.733327 | F32: =+F31/H31*100 -> 0 | G32: =+G31/H31*100 -> 1.2666735 | H32: =SUM(E32:G32) -> 100 | K32: =H31/D31*100 -> 85.774085 | L32: =100-K32 -> 14.225915 | R32: M | W32: =SUM(T32:V32) -> 0 | AI32: =SUM(AF32:AH32) -> 0
B33: KẾ HOẠCH 50*50 BÓNG | C33: m2 | D33: =AE92 -> 23338.462 | E33: =AF92 -> 20934.6 | F33: =AG92 -> 1137.75 | G33: =AH92 -> 682.65 | H33: =AI92 -> 22755 | I33: =AJ92 -> 1.85 | J33: =AK92 -> 12300 | N33: 100 | Q33: T10 | R33: PN | W33: =SUM(T33:V33) -> 0 | AD33: T10 | AI33: =SUM(AF33:AH33) -> 0
C34: % | E34: 92 | F34: 5 | G34: 3 | H34: =SUM(E34:G34) -> 100 | K34: 97.5 | L34: =100-K34 -> 2.5 | R34: PSG | W34: =SUM(T34:V34) -> 0 | AI34: =SUM(AF34:AH34) -> 0
B35: THỰC HIỆN 50*50 BÓNG | C35: m2 | D35: =S92 -> 23615 | E35: =T92 -> 79593 | F35: =U92 -> 0 | G35: =V92 -> 8863.5 | H35: =W92 -> 88456.5 | I35: =X92 -> 6.7854032 | J35: =Y92 -> #DIV/0! | L35: =Z92 -> 0 | M35: =AA92 -> 0 | N35: =AB92 -> 146 | R35: M | W35: =SUM(T35:V35) -> 0 | AI35: =SUM(AF35:AH35) -> 0
C36: % | E36: =+E35/H35*100 -> 89.979821 | F36: =+F35/H35*100 -> 0 | G36: =+G35/H35*100 -> 10.020179 | H36: =SUM(E36:G36) -> 100 | K36: =H35/D35*100 -> 374.5776 | L36: =100-K36 -> -274.5776 | Q36: T11 | R36: PN | W36: =SUM(T36:V36) -> 0 | AD36: T11 | AI36: =SUM(AF36:AH36) -> 0
B37: KẾ HOẠCH 50*50 | C37: m2 | D37: =D29+D33 -> 511593.03 | E37: =E29+E33 -> 467371.42 | F37: =F29+F33 -> 18682.058 | G37: =G29+G33 -> 13505.479 | H37: =H29+H33 -> 499558.96 | I37: =I29+I33 -> 40 | J37: =H37/I37+11 -> 12499.974 | N37: 100
C38: % | E38: 92 | F38: 5 | G38: 3 | H38: =SUM(E38:G38) -> 100 | K38: 97.5 | L38: =100-K38 -> 2.5
B39: THỰC HIỆN 50*50 | C39: m2 | D39: =D31+D35 -> 520634 | E39: =E31+E35 -> 500506.5 | F39: =F31+F35 -> 0 | G39: =G31+G35 -> 14263.5 | H39: =H31+H35 -> 514770 | I39: =I31+I35 -> 40 | J39: =H39/I39 -> 12869.25 | K39: =H39/D39*100 -> 98.873681 | L39: =100-K39 -> 1.1263191 | N39: 146
C40: % | E40: =+E39/H39*100 -> 97.229151 | F40: =+F39/H39*100 -> 0 | G40: =+G39/H39*100 -> 2.7708491 | H40: =SUM(E40:G40) -> 100 | K40: =H39/D39*100 -> 98.873681 | L40: =100-K40 -> 1.1263191
B41: KẾ HOẠCH 60*60 BÓNG | C41: m2 | D41: =AE121 -> 117312.82 | E41: =AF121 -> 101798.2 | F41: =AG121 -> 5719 | G41: =AH121 -> 6862.8 | H41: =AI121 -> 114380 | I41: =AJ121 -> 9.5 | J41: =AK121 -> 12040 | N41: 100 | R41: PSG | W41: =SUM(T41:V41) -> 0 | AI41: =SUM(AF41:AH41) -> 0
...

Sheet TH Thương hiệu DC2
A5: Thương hiệu | C5: ĐVT | D5: Thực Hiện | H5: Tỷ lệ | I5: Ghi chú
D6: A1 | E6: A | F6: B | G6: Tổng A1+A+B | H6: % | L6: SL (M2) | M6: T1 | N6: T2 | O6: T3 | P6: T4 | Q6: T5 | R6: T6 | S6: T7 | T6: T8 | U6: T9 | V6: T10 | W6: T11 | X6: T12 | Y6: Tổng:
A7: Luxury | C7: m2 | D7: =Y7 -> 569905.24 | E7: =Y8 -> 184.32 | F7: =Y9 -> 47363.96 | G7: =SUM(D7:F7) -> 617453.52 | I7: Sản lượng men Panson 40X80 | L7: A1 | O7: ='T3.2025 '!F89 -> 214442.24 | P7: 123295 | Q7: ='T5.2025'!F170 -> 6464 | R7: ='T6.2025'!F172 -> 225704 | Y7: =SUM(M7:X7) -> 569905.24
C8: % | D8: =D7/$G$7*100 -> 92.299294 | E8: =E7/$G$7*100 -> 0.02985164 | F8: =F7/$G$7*100 -> 7.6708543 | G8: =SUM(D8:F8) -> 100 | H8: =G7/$G$37*100 -> 58.120132 | L8: A | O8: ='T3.2025 '!G89 -> 184.32 | Y8: =SUM(M8:X8) -> 184.32
L9: B | O9: ='T3.2025 '!H89 -> 22239 | P9: 9684 | Q9: ='T5.2025'!H170 -> 1728 | R9: ='T6.2025'!H172 -> 13712.96 | Y9: =SUM(M9:X9) -> 47363.96
A10: Green Era | C10: m2 | D10: =Y10 -> 36316.04 | E10: =Y11 -> 0 | F10: =Y12 -> 1901.6 | G10: =SUM(D10:F10) -> 38217.64 | L10: A1 | O10: ='T3.2025 '!F99 -> 9719.04 | P10: 8637 | R10: ='T6.2025'!F182 -> 17960 | Y10: =SUM(M10:X10) -> 36316.04
C11: % | D11: =D10/$G$10*100 -> 95.024287 | E11: =E10/$G$10*100 -> 0 | F11: =F10/$G$10*100 -> 4.9757128 | G11: =SUM(D11:F11) -> 100 | H11: =G10/$G$37*100 -> 3.5973789 | L11: A | O11: ='T3.2025 '!G99 -> 0 | Y11: =SUM(M11:X11) -> 0
L12: B | O12: ='T3.2025 '!H99 -> 880 | P12: 388 | R12: ='T6.2025'!H182 -> 633.6 | Y12: =SUM(M12:X12) -> 1901.6
A13: Crown | C13: m2 | D13: =Y13 -> 75054.56 | E13: =Y14 -> 0 | F13: =Y15 -> 5907.76 | G13: =SUM(D13:F13) -> 80962.32 | L13: A1 | O13: ='T3.2025 '!F91 -> 12367.36 | P13: 13060 | Q13: ='T5.2025'!F172 -> 4672 | R13: ='T6.2025'!F178 -> 44955.2 | Y13: =SUM(M13:X13) -> 75054.56
C14: % | D14: =D13/$G$13*100 -> 92.703075 | E14: =E13/$G$13*100 -> 0 | F14: =F13/$G$13*100 -> 7.2969253 | G14: =SUM(D14:F14) -> 100 | H14: =G13/$G$37*100 -> 7.6208825 | L14: A | Y14: =SUM(M14:X14) -> 0
L15: B | O15: ='T3.2025 '!H91 -> 2378.24 | P15: 782 | Q15: ='T5.2025'!H172 -> 640 | R15: ='T6.2025'!H178 -> 2107.52 | Y15: =SUM(M15:X15) -> 5907.76
A16: Green Home | C16: m2 | D16: =Y16 -> 34275.12 | E16: =Y17 -> 0 | F16: =Y18 -> 1752.44 | G16: =SUM(D16:F16) -> 36027.56 | L16: A1 | O16: ='T3.2025 '!F93 -> 8145.92 | P16: 4630 | Q16: ='T5.2025'!F174 -> 5598.4 | R16: ='T6.2025'!F184 -> 15900.8 | Y16: =SUM(M16:X16) -> 34275.12
C17: % | D17: =D16/$G$16*100 -> 95.135835 | E17: =E16/$G$16*100 -> 0 | F17: =F16/$G$16*100 -> 4.8641651 | G17: =SUM(D17:F17) -> 100 | H17: =G16/$G$37*100 -> 3.3912294 | L17: A | Y17: =SUM(M17:X17) -> 0
L18: B | O18: ='T3.2025 '!H93 -> 586.24 | P18: 467 | Q18: ='T5.2025'!H174 -> 64 | R18: ='T6.2025'!H184 -> 635.2 | Y18: =SUM(M18:X18) -> 1752.44
A19: Lustile | C19: m2 | D19: =Y19 -> 36629.76 | E19: =Y20 -> 0 | F19: =Y21 -> 3620 | G19: =SUM(D19:F19) -> 40249.76 | L19: A1 | O19: ='T3.2025 '!F95 -> 36629.76 | Y19: =SUM(M19:X19) -> 36629.76
C20: % | D20: =D19/$G$25*100 -> 92.378928 | E20: =E19/$G$25*100 -> 0 | F20: =F19/$G$25*100 -> 9.1295089 | G20: =SUM(D20:F20) -> 101.50844 | H20: =G19/$G$37*100 -> 3.7886599 | L20: A | Y20: =SUM(M20:X20) -> 0
L21: B | O21: ='T3.2025 '!H95 -> 3620 | Y21: =SUM(M21:X21) -> 3620
A22: Top One | C22: m2 | D22: =Y22 -> 121266.36 | E22: =Y23 -> 0 | F22: =Y24 -> 9059.28 | G22: =SUM(D22:F22) -> 130325.64 | L22: A1 | O22: ='T3.2025 '!F101 -> 49378.56 | P22: 29859 | R22: ='T6.2025'!F174 -> 42028.8 | Y22: =SUM(M22:X22) -> 121266.36
C23: % | D23: =D22/$G$25*100 -> 305.82937 | E23: =E22/$G$25*100 -> 0 | F23: =F22/$G$25*100 -> 22.847176 | G23: =SUM(D23:F23) -> 328.67654 | H23: =G22/$G$37*100 -> 12.26739 | L23: A | Y23: =SUM(M23:X23) -> 0
L24: B | O24: ='T3.2025 '!H101 -> 3176.96 | P24: 2706 | R24: ='T6.2025'!H174 -> 3176.32 | Y24: =SUM(M24:X24) -> 9059.28
A25: Havira | C25: m2 | D25: =Y25 -> 37362.72 | E25: =Y26 -> 0 | F25: =Y27 -> 2288.92 | G25: =SUM(D25:F25) -> 39651.64 | L25: A1 | O25: ='T3.2025 '!F97 -> 3749.12 | P25: 19628 | R25: ='T6.2025'!F180 -> 13985.6 | Y25: =SUM(M25:X25) -> 37362.72
C26: % | D26: =D25/$G$25*100 -> 94.227427 | E26: =E25/$G$25*100 -> 0 | F26: =F25/$G$25*100 -> 5.7725733 | G26: =SUM(D26:F26) -> 100 | H26: =G25/$G$37*100 -> 3.7323596 | L26: A | O26: ='T3.2025 '!G97 -> 0 | Y26: =SUM(M26:X26) -> 0
L27: B | O27: ='T3.2025 '!H97 -> 398.64 | P27: 1345 | R27: ='T6.2025'!H180 -> 545.28 | Y27: =SUM(M27:X27) -> 2288.92
A28: Espana | C28: m2 | D28: =Y28 -> 38325.8 | E28: =Y29 -> 0 | F28: =Y30 -> 2062.84 | G28: =SUM(D28:F28) -> 40388.64 | L28: A1 | P28: 13473 | R28: ='T6.2025'!F176 -> 24852.8 | Y28: =SUM(M28:X28) -> 38325.8
C29: % | D29: =D28/$G$25*100 -> 96.65628 | E29: =E28/$G$25*100 -> 0 | F29: =F28/$G$25*100 -> 5.2024078 | G29: =SUM(D29:F29) -> 101.85869 | H29: =G28/$G$37*100 -> 3.8017325 | L29: A | Y29: =SUM(M29:X29) -> 0
L30: B | P30: 1059 | R30: ='T6.2025'!H176 -> 1003.84 | Y30: =SUM(M30:X30) -> 2062.84
A31: Pana Tile | C31: m2 | D31: =Y31 -> 35942.8 | E31: =Y32 -> 0 | F31: =Y33 -> 2278.08 | G31: =SUM(D31:F31) -> 38220.88 | L31: A1 | P31: 13850 | R31: ='T6.2025'!F186 -> 22092.8 | Y31: =SUM(M31:X31) -> 35942.8
C32: % | D32: =D31/$G$25*100 -> 90.64644 | E32: =E31/$G$25*100 -> 0 | F32: =F31/$G$25*100 -> 5.7452353 | G32: =SUM(D32:F32) -> 96.391675 | H32: =G31/$G$37*100 -> 3.5976839 | L32: A | Y32: =SUM(M32:X32) -> 0
L33: B | P33: 864 | R33: ='T6.2025'!H186 -> 1414.08 | Y33: =SUM(M33:X33) -> 2278.08
A34: Unitile | C34: m2 | D34: =Y34 -> 877 | E34: =Y35 -> 0 | F34: =Y36 -> 0 | G34: =SUM(D34:F34) -> 877 | L34: A1 | P34: 877 | Y34: =SUM(M34:X34) -> 877
C35: % | D35: =D34/$G$25*100 -> 2.2117622 | E35: =E34/$G$25*100 -> 0 | F35: =F34/$G$25*100 -> 0 | G35: =SUM(D35:F35) -> 2.2117622 | H35: =G34/$G$37*100 -> 0.082550919 | L35: A | Y35: =SUM(M35:X35) -> 0
L36: B | Y36: =SUM(M36:X36) -> 0
A37: Tổng men Panson 40X80 | C37: m2 | D37: =D7+D10+D13+D16+D19+D22+D25+D28+D31+D34 -> 985955.4 | E37: =E7+E10+E13+E16+E19+E22+E25+E28+E31+E34 -> 184.32 | F37: =F7+F10+F13+F16+F19+F22+F25+F28+F31+F34 -> 76234.88 | G37: =G7+G10+G13+G16+G19+G22+G25+G28+G31+G34 -> 1062374.6 | L37: A1 | Y37: =SUM(M37:X37) -> 0
C38: % | D38: =D37/$G$37*100 -> 92.806756 | E38: =E37/$G$37*100 -> 0.017349812 | F38: =F37/$G$37*100 -> 7.1758945 | G38: =SUM(D38:F38) -> 100 | L38: A | Y38: =SUM(M38:X38) -> 0
L39: B | Y39: =SUM(M39:X39) -> 0
A40: Luxury | C40: m2 | D40: =Y40 -> 58545 | E40: =Y41 -> 0 | F40: =Y42 -> 4089.24 | G40: =SUM(D40:F40) -> 62634.24 | I40: Sản lượng men Bóng 60x60 | L40: A1 | M40: ='T1.2025'!F97 -> 0 | Q40: ='T5.2025'!F138 -> 58545 | Y40: =SUM(M40:X40) -> 58545
C41: % | D41: =D40/$G$40*100 -> 93.471239 | E41: =E40/$G$40*100 -> 0 | F41: =F40/$G$40*100 -> 6.5287613 | G41: =SUM(D41:F41) -> 100 | H41: =G40/$G$67*100 -> 63.114745 | L41: A | M41: ='T1.2025'!G97 -> 0 | Y41: =SUM(M41:X41) -> 0
L42: B | M42: ='T1.2025'!H97 -> 0 | Q42: ='T5.2025'!H138 -> 4089.24 | Y42: =SUM(M42:X42) -> 4089.24
A43: Espana | C43: m2 | D43: =Y43 -> 19218.6 | E43: =Y44 -> 0 | F43: =Y45 -> 537.84 | G43: =SUM(D43:F43) -> 19756.44 | L43: A1 | M43: ='T1.2025'!F99 -> 0 | Q43: ='T5.2025'!F146 -> 19218.6 | Y43: =SUM(M43:X43) -> 19218.6
C44: % | D44: =D43/$G$43*100 -> 97.277647 | E44: =E43/$G$43*100 -> 0 | F44: =F43/$G$43*100 -> 2.7223528 | G44: =SUM(D44:F44) -> 100 | H44: =G43/$G$67*100 -> 19.908004 | L44: A | M44: ='T1.2025'!G99 -> 0 | Y44: =SUM(M44:X44) -> 0
...

Sheet TH Thương hiệu DC1
A5: Thương hiệu | C5: ĐVT | D5: Thực Hiện | H5: Tỷ lệ | I5: Ghi chú
D6: A1 | E6: A | F6: B | G6: Tổng A1+A+B | H6: % | L6: SL (M2) | M6: T1 | N6: T2 | O6: T3 | P6: T4 | Q6: T5 | R6: T6 | S6: T7 | T6: T8 | U6: T9 | V6: T10 | W6: T11 | X6: T12 | Y6: Tổng: | Z6: Tổng C: | AA6: Số ngày SX
A7: Luxury | C7: m2 | D7: =Y7 -> 111178.56 | E7: =Y8 -> 3644.64 | F7: =Y9 -> 18577.44 | G7: =SUM(D7:F7) -> 133400.64 | I7: Sản lượng men Panson | L7: A1 | M7: ='T1.2025'!F45 -> 0 | O7: ='T3.2025 '!F57 -> 64971.36 | P7: 41916 | Q7: ='T5.2025'!F70 -> 4291.2 | Y7: =SUM(M7:X7) -> 111178.56
C8: % | D8: =D7/$G$7*100 -> 83.341849 | E8: =E7/$G$7*100 -> 2.7321008 | F8: =F7/$G$7*100 -> 13.92605 | G8: =SUM(D8:F8) -> 100 | H8: =G7/$G$70*100 -> 7.8349273 | L8: A | M8: ='T1.2025'!G45 -> 0 | O8: ='T3.2025 '!G57 -> 2617.92 | P8: 853.92 | Q8: ='T5.2025'!G70 -> 172.8 | Y8: =SUM(M8:X8) -> 3644.64
L9: B | M9: ='T1.2025'!H45 -> 0 | O9: ='T3.2025 '!H57 -> 15330.24 | P9: 2443.68 | Q9: ='T5.2025'!H70 -> 803.52 | Y9: =SUM(M9:X9) -> 18577.44
A10: Green Era | C10: m2 | D10: =Y10 -> 0 | E10: =Y11 -> 0 | F10: =Y12 -> 0 | G10: =SUM(D10:F10) -> 0 | L10: A1 | Y10: =SUM(M10:X10) -> 0
C11: % | D11: =D10/$G$10*100 -> #DIV/0! | E11: =E10/$G$10*100 -> #DIV/0! | F11: =F10/$G$10*100 -> #DIV/0! | G11: =SUM(D11:F11) -> #DIV/0! | H11: =G10/$G$70*100 -> 0 | L11: A | Y11: =SUM(M11:X11) -> 0
L12: B | Y12: =SUM(M12:X12) -> 0
A13: Lustile | C13: m2 | D13: =Y13 -> 164010.24 | E13: =Y14 -> 0 | F13: =Y15 -> 0 | G13: =SUM(D13:F13) -> 164010.24 | L13: A1 | M13: ='T1.2025'!F47 -> 0 | O13: ='T3.2025 '!F55 -> 164010.24 | Y13: =SUM(M13:X13) -> 164010.24
C14: % | D14: =D13/$G$13*100 -> 100 | E14: =E13/$G$13*100 -> 0 | F14: =F13/$G$13*100 -> 0 | G14: =SUM(D14:F14) -> 100 | H14: =G13/$G$70*100 -> 9.6326997 | L14: A | M14: ='T1.2025'!G47 -> 0 | Y14: =SUM(M14:X14) -> 0
L15: B | M15: ='T1.2025'!H47 -> 0 | O15: ='T3.2025 '!H55 -> 0 | Y15: =SUM(M15:X15) -> 0
A16: Sahado | C16: m2 | D16: =Y16 -> 26395.2 | E16: =Y17 -> 0 | F16: =Y18 -> 2674.08 | G16: =SUM(D16:F16) -> 29069.28 | L16: A1 | M16: ='T1.2025'!F49 -> 0 | O16: ='T3.2025 '!F59 -> 2779.2 | Q16: ='T5.2025'!F74 -> 23616 | Y16: =SUM(M16:X16) -> 26395.2
C17: % | D17: =D16/$G$16*100 -> 90.801011 | E17: =E16/$G$16*100 -> 0 | F17: =F16/$G$16*100 -> 9.1989894 | G17: =SUM(D17:F17) -> 100 | H17: =G16/$G$70*100 -> 1.7073059 | L17: A | M17: ='T1.2025'!G49 -> 0 | Q17: ='T5.2025'!G74 -> 0 | Y17: =SUM(M17:X17) -> 0
L18: B | M18: ='T1.2025'!H49 -> 0 | O18: ='T3.2025 '!H59 -> 259.2 | Q18: ='T5.2025'!H74 -> 2414.88 | Y18: =SUM(M18:X18) -> 2674.08
A19: Havira | C19: m2 | D19: =Y19 -> 5518.4 | E19: =Y20 -> 0 | F19: =Y21 -> 634.84 | G19: =SUM(D19:F19) -> 6153.24 | L19: A1 | P19: 3020 | Q19: ='T5.2025'!F72 -> 2498.4 | Y19: =SUM(M19:X19) -> 5518.4
C20: % | D20: =D19/$G$19*100 -> 89.682834 | E20: =E19/$G$19*100 -> 0 | F20: =F19/$G$19*100 -> 10.317166 | G20: =SUM(D20:F20) -> 100 | H20: =G19/$G$70*100 -> 0.36139398 | L20: A | Q20: ='T5.2025'!G72 -> 0 | Y20: =SUM(M20:X20) -> 0
L21: B | P21: 187 | Q21: ='T5.2025'!H72 -> 447.84 | Y21: =SUM(M21:X21) -> 634.84
A22: Tổng men Panson: | C22: m2 | D22: =D7+D10+D13+D16+D19 -> 307102.4 | E22: =E7+E10+E13+E16+E19 -> 3644.64 | F22: =F7+F10+F13+F16+F19 -> 21886.36 | G22: =SUM(D22:F22) -> 332633.4 | L22: A1
C23: % | D23: =D22/$G$22*100 -> 92.324583 | E23: =E22/$G$22*100 -> 1.0956927 | F23: =F22/$G$22*100 -> 6.5797241 | G23: =SUM(D23:F23) -> 100 | H23: =G22/$G$70*100 -> 19.536327 | L23: A
L24: B
A25: Grandcera chung | C25: m2 | D25: =Y25 -> 774043.2 | E25: =Y26 -> 36695.36 | F25: =Y27 -> 41104.6 | G25: =SUM(D25:F25) -> 851843.16 | I25: Sản lượng men Phương Nam | L25: A1 | M25: ='T1.2025'!F53 -> 0 | N25: ='T2.2025 '!F49 -> 76659.84 | O25: ='T3.2025 '!F37 -> 152226.72 | P25: 228780 | Q25: ='T5.2025'!F52 -> 151758.72 | R25: ='T6.2025'!F54 -> 164617.92 | Y25: =SUM(M25:X25) -> 774043.2
C26: % | D26: =D25/$G$25*100 -> 90.866868 | E26: =E25/$G$25*100 -> 4.3077601 | F26: =F25/$G$25*100 -> 4.8253718 | G26: =SUM(D26:F26) -> 100 | H26: =G25/$G$70*100 -> 50.030713 | L26: A | M26: ='T1.2025'!G53 -> 0 | N26: ='T2.2025 '!G49 -> 5675.04 | O26: ='T3.2025 '!G37 -> 5929.92 | P26: 8696 | Q26: ='T5.2025'!G52 -> 7107.84 | R26: ='T6.2025'!G54 -> 9286.56 | Y26: =SUM(M26:X26) -> 36695.36
L27: B | M27: ='T1.2025'!H53 -> 0 | N27: ='T2.2025 '!H49 -> 4896 | O27: ='T3.2025 '!H37 -> 6896.16 | P27: 9871 | Q27: ='T5.2025'!H52 -> 8069.76 | R27: ='T6.2025'!H54 -> 11371.68 | Y27: =SUM(M27:X27) -> 41104.6
A28: Grandcera độc quyền | C28: m2 | D28: =Y28 -> 0 | E28: =Y29 -> 0 | F28: =Y30 -> 0 | G28: =SUM(D28:F28) -> 0 | L28: A1 | Y28: =SUM(M28:X28) -> 0
C29: % | D29: =D28/$H$130*100 -> #DIV/0! | E29: =E28/$H$130*100 -> #DIV/0! | F29: =F28/$H$130*100 -> #DIV/0! | G29: =SUM(D29:F29) -> #DIV/0! | H29: =G28/$G$70*100 -> 0 | L29: A | Y29: =SUM(M29:X29) -> 0
L30: B | Y30: =SUM(M30:X30) -> 0
A31: Crown | C31: m2 | D31: =Y31 -> 83359.76 | E31: =Y32 -> 0 | F31: =Y33 -> 6028.12 | G31: =SUM(D31:F31) -> 89387.88 | L31: A1 | M31: ='T1.2025'!F55 -> 0 | N31: ='T2.2025 '!F51 -> 5196.96 | O31: ='T3.2025 '!F41 -> 11684.16 | P31: 19742 | Q31: ='T5.2025'!F56 -> 27426.24 | R31: ='T6.2025'!F58 -> 19310.4 | Y31: =SUM(M31:X31) -> 83359.76
C32: % | D32: =D31/$G$31*100 -> 93.256222 | E32: =E31/$G$31*100 -> 0 | F32: =F31/$G$31*100 -> 6.7437778 | G32: =SUM(D32:F32) -> 100 | H32: =G31/$G$70*100 -> 5.2499564 | L32: A | M32: ='T1.2025'!G55 -> 0 | N32: ='T2.2025 '!G51 -> 0 | Q32: ='T5.2025'!G56 -> 0 | Y32: =SUM(M32:X32) -> 0
L33: B | M33: ='T1.2025'!H55 -> 0 | N33: ='T2.2025 '!H51 -> 440.64 | O33: ='T3.2025 '!H41 -> 662.4 | P33: 1639 | Q33: ='T5.2025'!H56 -> 1558.08 | R33: ='T6.2025'!H58 -> 1728 | Y33: =SUM(M33:X33) -> 6028.12
A34: Esspana | C34: m2 | D34: =Y34 -> 32997.36 | E34: =Y35 -> 0 | F34: =Y36 -> 3757.08 | G34: =SUM(D34:F34) -> 36754.44 | L34: A1 | M34: ='T1.2025'!F57 -> 0 | O34: ='T3.2025 '!F39 -> 624.96 | P34: 14934 | Q34: ='T5.2025'!F54 -> 8082.72 | R34: ='T6.2025'!F56 -> 9355.68 | Y34: =SUM(M34:X34) -> 32997.36
C35: % | D35: =D34/$G$34*100 -> 89.777888 | E35: =E34/$G$34*100 -> 0 | F35: =F34/$G$34*100 -> 10.222112 | G35: =SUM(D35:F35) -> 100 | H35: =G34/$G$70*100 -> 2.158673 | L35: A | M35: ='T1.2025'!G57 -> 0 | Q35: ='T5.2025'!G54 -> 0 | Y35: =SUM(M35:X35) -> 0
L36: B | M36: ='T1.2025'!H57 -> 0 | O36: ='T3.2025 '!H39 -> 79.2 | P36: 1083 | Q36: ='T5.2025'!H54 -> 519.84 | R36: ='T6.2025'!H56 -> 2075.04 | Y36: =SUM(M36:X36) -> 3757.08
A37: Green Era | C37: m2 | D37: =Y37 -> 49259.12 | E37: =Y38 -> 1691.56 | F37: =Y39 -> 2500.8 | G37: =SUM(D37:F37) -> 53451.48 | L37: A1 | O37: ='T3.2025 '!F47 -> 9253.44 | P37: 18518 | Q37: ='T5.2025'!F62 -> 8536.32 | R37: ='T6.2025'!F64 -> 12951.36 | Y37: =SUM(M37:X37) -> 49259.12
C38: % | D38: =D37/$H$136*100 -> #DIV/0! | E38: =E37/$H$136*100 -> #DIV/0! | F38: =F37/$H$136*100 -> #DIV/0! | G38: =SUM(D38:F38) -> #DIV/0! | H38: =G37/$G$70*100 -> 3.1393287 | L38: A | O38: ='T3.2025 '!G47 -> 365.76 | P38: 397 | Q38: ='T5.2025'!G62 -> 432 | R38: ='T6.2025'!G64 -> 496.8 | Y38: =SUM(M38:X38) -> 1691.56
L39: B | O39: ='T3.2025 '!H47 -> 217.44 | P39: 1032 | Q39: ='T5.2025'!H62 -> 472.32 | R39: ='T6.2025'!H64 -> 779.04 | Y39: =SUM(M39:X39) -> 2500.8
A40: Sahado | C40: m2 | D40: =Y40 -> 31897.44 | E40: =Y41 -> 0 | F40: =Y42 -> 2551.6 | G40: =SUM(D40:F40) -> 34449.04 | L40: A1 | N40: ='T2.2025 '!F53 -> 1958.4 | O40: ='T3.2025 '!F43 -> 2750.4 | P40: 19044 | Q40: ='T5.2025'!F58 -> 1929.6 | R40: ='T6.2025'!F60 -> 6215.04 | Y40: =SUM(M40:X40) -> 31897.44
C41: % | D41: =D40/$G$40*100 -> 92.593117 | E41: =E40/$G$40*100 -> 0 | F41: =F40/$G$40*100 -> 7.4068827 | G41: =G40/$G$40*100 -> 100 | H41: =G40/$G$70*100 -> 2.0232716 | L41: A | N41: ='T2.2025 '!G53 -> 0 | Q41: ='T5.2025'!G58 -> 0 | Y41: =SUM(M41:X41) -> 0
L42: B | N42: ='T2.2025 '!H53 -> 175.68 | O42: ='T3.2025 '!H43 -> 306.72 | P42: 1414 | Q42: ='T5.2025'!H58 -> 135.36 | R42: ='T6.2025'!H60 -> 519.84 | Y42: =SUM(M42:X42) -> 2551.6
A43: Pana Tile | C43: m2 | D43: =Y43 -> 29594.88 | E43: =Y44 -> 0 | F43: =Y45 -> 1762.56 | G43: =SUM(D43:F43) -> 31357.44 | L43: A1 | O43: ='T3.2025 '!F49 -> 8828.64 | Q43: ='T5.2025'!F64 -> 13389.12 | R43: ='T6.2025'!F66 -> 7377.12 | Y43: =SUM(M43:X43) -> 29594.88
C44: % | D44: =D43/$H$140*100 -> #DIV/0! | E44: =E43/$H$140*100 -> #DIV/0! | F44: =F43/$H$140*100 -> #DIV/0! | G44: =G43/$H$140*100 -> #DIV/0! | H44: =G43/$G$70*100 -> 1.8416948 | L44: A | Q44: ='T5.2025'!G64 -> 0 | Y44: =SUM(M44:X44) -> 0
...

Sheet TH Than 2025
A1: CÔNG TY CỔ PHẦN GẠCH MEN PHƯƠNG NAM
A2: Địa chỉ: Cụm CN VLXD Tân An, X. Tân An, H. Vĩnh Cửu, T. Đồng Nai
A3: Điện thoại: 0251 3684039 *** Email: gachmenphuongnam@gmail.com
A4: BÁO CÁO TIÊU HAO THAN 2 DC NĂM 2025
A5: STT | B5: KT | C5: Sản lượng (A1-A-B) | D5: KL Than cục | E5: Tiêu hao | F5: Xuất Cám | H5: Tiêu hao (cục + cám) | I5: Lĩnh bù | J5: Tiêu hao (cục + cám + lĩnh bù) | K5: Ghi chú
C6: m2 | D6: Kg | E6: Kg/ m2 | F6: Số lượng (Kg) | G6: Cám (%) | H6: Kg | I6: Kg | J6: Kg/ m2
A7: 1 | B7: 30X60 | C7: =B33 -> 1702641.7 | D7: =D33 -> 5003816 | E7: =D7/C7 -> 2.9388544 | F7: =E33 -> 519541 | G7: =F7/(D7+F7)*100 -> 9.4062542 | H7: =(D7+F7)/C7 -> 3.2439926 | I7: =F33 -> 34457 | J7: =(D7+F7+I7)/C7 -> 3.26423 | K7: DC1 SX lại từ ngày 22/02/2025
A8: 2 | B8: 40X80 | C8: =G33 -> 1062373.1 | D8: =I33 -> 3439724 | E8: =D8/C8 -> 3.2377739 | F8: =J33 -> 309127 | G8: =F8/(D8+F8)*100 -> 8.2459132 | H8: =(D8+F8)/C8 -> 3.5287517 | I8: =K33 -> 35288 | J8: =(D8+F8+I8)/C8 -> 3.5619679 | K8: DC2 SX lại từ ngày 05/03/2025: tháng 03-04-05-06
A9: 3 | B9: 40X60 | G9: =F9/(D9+F9)*100 -> #DIV/0!
A10: 3 | B10: 50X50 | C10: =L33 -> 514773.5 | D10: =N33 -> 1158501 | E10: =D10/C10 -> 2.2505063 | F10: =O33 -> 149956 | G10: =F10/(D10+F10)*100 -> 11.460522 | H10: =(D10+F10)/C10 -> 2.5418111 | I10: =P33 -> 2115 | J10: =(D10+F10+I10)/C10 -> 2.5459197 | K10: DC2 tháng 01-04-05
A11: 4 | B11: 60X60 | C11: =Q33 -> 116559 | D11: =S33 -> 224692 | E11: =D11/C11 -> 1.9277104 | F11: =T33 -> 39187 | G11: =F11/(D11+F11)*100 -> 14.850367 | H11: =(D11+F11)/C11 -> 2.2639093 | I11: =U33 -> 0 | J11: =(D11+F11+I11)/C11 -> 2.2639093 | K11: DC2 tháng 05
A12: Tổng năm 2 DC | C12: =SUM(C7:C11) -> 3396347.3 | D12: =SUM(D7:D11) -> 9826733 | E12: =D12/C12 -> 2.8933239 | F12: =SUM(F7:F11) -> 1017811 | G12: =SUM(G7:G11)/4 -> #DIV/0! | H12: =(D12+F12)/C12 -> 3.1930021 | I12: =SUM(I7:I11) -> 71860 | J12: =(D12+F12+I12)/C12 -> 3.2141601
A14: Trân trọng!
I15: Đồng Nai, ngày ... tháng 12 năm 2025
I16: P.TGĐ PT SX - KTCN
A19: THÁNG | B19: 300X600 (SX lại từ 22/02/25) | G19: 400X800 (SX lại từ 05/03/25): T3-T4-T5-T6 | L19: 500X500 ( T1-T4-T5 | Q19: 600X600 (T5 | V19: 400X600
B20: A1-A-B | C20: C | D20: Cục | E20: Cám | F20: Bù | G20: A1-A-B | H20: C | I20: Cục | J20: Cám | K20: Bù | L20: A1-A-B | M20: C | N20: Cục | O20: Cám | P20: Bù | Q20: A1-A-B | R20: C | S20: Cục | T20: Cám | U20: Bù | V20: A1-A-B | W20: C | X20: Cục | Y20: Cám | Z20: Bù
A21: 1 | L21: ='T1.2025'!F134 -> 115884.5 | N21: ='T1.2025'!I210 -> 245803 | O21: ='T1.2025'!L210 -> 21106 | P21: ='T1.2025'!O210 -> 355
A22: 2 | B22: ='T2.2025 '!I11 -> 102801.6 | C22: ='T2.2025 '!M11 -> 649.44 | D22: ='T2.2025 '!J86 -> 400363 | E22: ='T2.2025 '!M86 -> 21691 | F22: ='T2.2025 '!P86 -> 0
A23: 3 | B23: ='T3.2025 '!J154 -> 489176.73 | C23: ='T3.2025 '!M10 -> 1677.66 | D23: ='T3.2025 '!I154 -> 1499949 | E23: ='T3.2025 '!L154 -> 137444 | F23: ='T3.2025 '!O154 -> 16343 | G23: ='T3.2025 '!J165 -> 367895.04 | H23: ='T3.2025 '!M16 -> 1689.6 | I23: ='T3.2025 '!I165 -> 1301592 | J23: ='T3.2025 '!L165 -> 121885 | K23: ='T3.2025 '!O165 -> 14492
A24: 4 | B24: ='T4.2025 '!J196 -> 441077.76 | C24: ='T4.2025 '!M11 -> 1512 | D24: ='T4.2025 '!I196 -> 1280929 | E24: ='T4.2025 '!L196 -> 110494 | F24: ='T4.2025 '!O196 -> 7653 | G24: ='T4.2025 '!J202 -> 244602.88 | H24: ='T4.2025 '!M17 -> 1286.4 | I24: ='T4.2025 '!I202 -> 787687 | J24: ='T4.2025 '!L202 -> 67873 | K24: ='T4.2025 '!O202 -> 5105 | L24: ='T4.2025 '!I130 -> 148288.5 | M24: ='T4.2025 '!M23 -> 642 | N24: ='T4.2025 '!I208 -> 357263 | O24: ='T4.2025 '!L208 -> 30883 | P24: ='T4.2025 '!O208 -> 1760
A25: 5 | B25: ='T5.2025'!J265 -> 360989.28 | C25: ='T5.2025'!M11 -> 1689.12 | D25: ='T5.2025'!I265 -> 906891 | E25: ='T5.2025'!L265 -> 184210 | F25: ='T5.2025'!O265 -> 0 | G25: ='T5.2025'!J284 -> 19166.4 | H25: ='T5.2025'!M29 -> 240 | I25: ='T5.2025'!I284 -> 70279 | J25: ='T5.2025'!L284 -> 13564 | K25: ='T5.2025'!O284 -> 0 | L25: ='T5.2025'!J272 -> 250600.5 | M25: ='T5.2025'!M17 -> 1209 | N25: ='T5.2025'!I272 -> 555435 | O25: ='T5.2025'!L272 -> 97967 | P25: ='T5.2025'!O272 -> 0 | Q25: ='T5.2025'!J278 -> 116559 | R25: ='T5.2025'!M23 -> 712.8 | S25: ='T5.2025'!I278 -> 224692 | T25: ='T5.2025'!L278 -> 39187 | U25: ='T5.2025'!O278 -> 0
A26: 6 | B26: ='T6.2025'!J302 -> 308596.32 | C26: ='T6.2025'!M11 -> 1828.8 | D26: ='T6.2025'!I302 -> 915684 | E26: ='T6.2025'!L302 -> 65702 | F26: ='T6.2025'!O302 -> 10461 | G26: ='T6.2025'!J310 -> 430708.8 | H26: ='T6.2025'!M29 -> 2112 | I26: ='T6.2025'!I310 -> 1280166 | J26: ='T6.2025'!L310 -> 105805 | K26: ='T6.2025'!O310 -> 15691
A27: 7
A28: 8
A29: 9
A30: 10
A31: 11
A32: 12
A33: Tổng: | B33: =SUM(B21:B32) -> 1702641.7 | C33: =SUM(C21:C32) -> 7357.02 | D33: =SUM(D21:D32) -> 5003816 | E33: =SUM(E21:E32) -> 519541 | F33: =SUM(F21:F32) -> 34457 | G33: =SUM(G21:G32) -> 1062373.1 | H33: =SUM(H21:H32) -> 5328 | I33: =SUM(I21:I32) -> 3439724 | ... Z33: =SUM(Z21:Z32) -> 0
A34: Tổng C | B34: =SUM(B33:C33) -> 1709998.7 | G34: =SUM(G33:H33) -> 1067701.1 | L34: =SUM(L33:M33) -> 516624.5 | Q34: =SUM(Q33:R33) -> 117271.8 | V34: =SUM(V33:W33) -> 0
A37: - DC1 SX lại từ ngày 22/02/2025
A38: - DC2 SX lại từ ngày 05/03/25. Chạy 40x80 từ 05/03/25

Sheet 6 tháng đầu năm Than 2025 
A1: CÔNG TY CỔ PHẦN GẠCH MEN PHƯƠNG NAM
A2: Địa chỉ: Cụm CN VLXD Tân An, X. Tân An, H. Vĩnh Cửu, T. Đồng Nai
A3: Điện thoại: 0251 3684039 *** Email: gachmenphuongnam@gmail.com
A4: BÁO CÁO TIÊU HAO THAN 2 DC 6 THÁNG ĐẦU NĂM 2025
A5: STT | B5: KT | C5: Sản lượng (A1-A-B) | D5: KL Than cục | E5: Tiêu hao | F5: Xuất Cám | H5: Tiêu hao (cục + cám) | I5: Lĩnh bù | J5: Tiêu hao (cục + cám + lĩnh bù) | K5: Ghi chú
C6: m2 | D6: Kg | E6: Kg/ m2 | F6: Số lượng (Kg) | G6: Cám (%) | H6: Kg | I6: Kg | J6: Kg/ m2
A7: 1 | B7: 30X60 | C7: =B33 -> 1702641.7 | D7: =D33 -> 5003816 | E7: =D7/C7 -> 2.9388544 | F7: =E33 -> 519541 | G7: =F7/(D7+F7)*100 -> 9.4062542 | H7: =(D7+F7)/C7 -> 3.2439926 | I7: =F33 -> 34457 | J7: =(D7+F7+I7)/C7 -> 3.26423 | K7: DC1 Gạch ốp 30x60 SX từ ngày 22/02/2025
A8: 2 | B8: 40X80 | C8: =G33 -> 1062373.1 | D8: =I33 -> 3439724 | E8: =D8/C8 -> 3.2377739 | F8: =J33 -> 309127 | G8: =F8/(D8+F8)*100 -> 8.2459132 | H8: =(D8+F8)/C8 -> 3.5287517 | I8: =K33 -> 35288 | J8: =(D8+F8+I8)/C8 -> 3.5619679 | K8: DC2 Gạch ốp 40x80 sản xuất T3-T4-T5-T6
A9: 3 | B9: 40X60 | G9: =F9/(D9+F9)*100 -> #DIV/0!
A10: 3 | B10: 50X50 | C10: =L33 -> 514773.5 | D10: =N33 -> 1158501 | E10: =D10/C10 -> 2.2505063 | F10: =O33 -> 149956 | G10: =F10/(D10+F10)*100 -> 11.460522 | H10: =(D10+F10)/C10 -> 2.5418111 | I10: =P33 -> 2115 | J10: =(D10+F10+I10)/C10 -> 2.5459197 | K10: DC2 Gạch lát 50x50 sản xuất T1-T4-T5
A11: 4 | B11: 60X60 | C11: =Q33 -> 116559 | D11: =S33 -> 224692 | E11: =D11/C11 -> 1.9277104 | F11: =T33 -> 39187 | G11: =F11/(D11+F11)*100 -> 14.850367 | H11: =(D11+F11)/C11 -> 2.2639093 | I11: =U33 -> 0 | J11: =(D11+F11+I11)/C11 -> 2.2639093 | K11: DC2 Gạch lát 60x60 sản xuất T5
A12: Tổng 6 tháng đầu năm 2025 2 DC | C12: =SUM(C7:C11) -> 3396347.3 | D12: =SUM(D7:D11) -> 9826733 | E12: =D12/C12 -> 2.8933239 | F12: =SUM(F7:F11) -> 1017811 | G12: =F12/(F12+D12)*100 -> 9.3854661 | H12: =(D12+F12)/C12 -> 3.1930021 | I12: =SUM(I7:I11) -> 71860 | J12: =(D12+F12+I12)/C12 -> 3.2141601
A13: 06 Tháng cuối năm 2024 | C13: ='[2]6 tháng cuối năm a viện'!$J$98 -> #REF! | D13: ='[2]6 tháng cuối năm a viện'!$H$98 -> #REF! | E13: =D13/C13 -> #REF! | F13: ='[2]6 tháng cuối năm a viện'!$L$98 -> #REF! | G13: =F13/(F13+D13)*100 -> #REF! | H13: =(D13+F13)/C13 -> #REF! | I13: ='[2]6 tháng cuối năm a viện'!$Q$98 -> #REF! | J13: =(D13+F13+I13)/C13 -> #REF!
A14: Trân trọng!
I15: Đồng Nai, ngày 08 tháng 07 năm 2025
I16: P.TGĐ PT SX
A19: THÁNG | B19: 300X600 (SX lại từ 22/02/25) | G19: 400X800 (SX lại từ 05/03/25): T3-T4-T5-T6 | L19: 500X500 ( T1-T4-T5 | Q19: 600X600 (T5 | V19: 400X600
B20: A1-A-B | C20: C | D20: Cục | E20: Cám | F20: Bù | G20: A1-A-B | H20: C | I20: Cục | J20: Cám | K20: Bù | L20: A1-A-B | M20: C | N20: Cục | O20: Cám | P20: Bù | Q20: A1-A-B | R20: C | S20: Cục | T20: Cám | U20: Bù | V20: A1-A-B | W20: C | X20: Cục | Y20: Cám | Z20: Bù
A21: 1 | L21: ='T1.2025'!F134 -> 115884.5 | N21: ='T1.2025'!I210 -> 245803 | O21: ='T1.2025'!L210 -> 21106 | P21: ='T1.2025'!O210 -> 355
A22: 2 | B22: ='T2.2025 '!I11 -> 102801.6 | C22: ='T2.2025 '!M11 -> 649.44 | D22: ='T2.2025 '!J86 -> 400363 | E22: ='T2.2025 '!M86 -> 21691 | F22: ='T2.2025 '!P86 -> 0
A23: 3 | B23: ='T3.2025 '!J154 -> 489176.73 | C23: ='T3.2025 '!M10 -> 1677.66 | D23: ='T3.2025 '!I154 -> 1499949 | E23: ='T3.2025 '!L154 -> 137444 | F23: ='T3.2025 '!O154 -> 16343 | G23: ='T3.2025 '!J165 -> 367895.04 | H23: ='T3.2025 '!M16 -> 1689.6 | I23: ='T3.2025 '!I165 -> 1301592 | J23: ='T3.2025 '!L165 -> 121885 | K23: ='T3.2025 '!O165 -> 14492
A24: 4 | B24: ='T4.2025 '!J196 -> 441077.76 | C24: ='T4.2025 '!M11 -> 1512 | D24: ='T4.2025 '!I196 -> 1280929 | E24: ='T4.2025 '!L196 -> 110494 | F24: ='T4.2025 '!O196 -> 7653 | G24: ='T4.2025 '!J202 -> 244602.88 | H24: ='T4.2025 '!M17 -> 1286.4 | I24: ='T4.2025 '!I202 -> 787687 | J24: ='T4.2025 '!L202 -> 67873 | K24: ='T4.2025 '!O202 -> 5105 | L24: ='T4.2025 '!I130 -> 148288.5 | M24: ='T4.2025 '!M23 -> 642 | N24: ='T4.2025 '!I208 -> 357263 | O24: ='T4.2025 '!L208 -> 30883 | P24: ='T4.2025 '!O208 -> 1760
A25: 5 | B25: ='T5.2025'!J265 -> 360989.28 | C25: ='T5.2025'!M11 -> 1689.12 | D25: ='T5.2025'!I265 -> 906891 | E25: ='T5.2025'!L265 -> 184210 | F25: ='T5.2025'!O265 -> 0 | G25: ='T5.2025'!J284 -> 19166.4 | H25: ='T5.2025'!M29 -> 240 | I25: ='T5.2025'!I284 -> 70279 | J25: ='T5.2025'!L284 -> 13564 | K25: ='T5.2025'!O284 -> 0 | L25: ='T5.2025'!J272 -> 250600.5 | M25: ='T5.2025'!M17 -> 1209 | N25: ='T5.2025'!I272 -> 555435 | O25: ='T5.2025'!L272 -> 97967 | P25: ='T5.2025'!O272 -> 0 | Q25: ='T5.2025'!J278 -> 116559 | R25: ='T5.2025'!M23 -> 712.8 | S25: ='T5.2025'!I278 -> 224692 | T25: ='T5.2025'!L278 -> 39187 | U25: ='T5.2025'!O278 -> 0
A26: 6 | B26: ='T6.2025'!J302 -> 308596.32 | C26: ='T6.2025'!M11 -> 1828.8 | D26: ='T6.2025'!I302 -> 915684 | E26: ='T6.2025'!L302 -> 65702 | F26: ='T6.2025'!O302 -> 10461 | G26: ='T6.2025'!J310 -> 430708.8 | H26: ='T6.2025'!M29 -> 2112 | I26: ='T6.2025'!I310 -> 1280166 | J26: ='T6.2025'!L310 -> 105805 | K26: ='T6.2025'!O310 -> 15691
A27: 7
A28: 8
A29: 9
A30: 10
A31: 11
A32: 12
A33: Tổng: | B33: =SUM(B21:B32) -> 1702641.7 | C33: =SUM(C21:C32) -> 7357.02 | D33: =SUM(D21:D32) -> 5003816 | E33: =SUM(E21:E32) -> 519541 | F33: =SUM(F21:F32) -> 34457 | G33: =SUM(G21:G32) -> 1062373.1 | H33: =SUM(H21:H32) -> 5328 | I33: =SUM(I21:I32) -> 3439724 | ... Z33: =SUM(Z21:Z32) -> 0
A34: Tổng C | B34: =SUM(B33:C33) -> 1709998.7 | G34: =SUM(G33:H33) -> 1067701.1 | L34: =SUM(L33:M33) -> 516624.5 | Q34: =SUM(Q33:R33) -> 117271.8 | V34: =SUM(V33:W33) -> 0
A37: - DC1 SX lại từ ngày 22/02/2025
A38: - DC2 SX lại từ ngày 05/03/25. Chạy 40x80 từ 05/03/25

Sheet Form mẫu
A1: CÔNG TY CỔ PHẦN GẠCH MEN PHƯƠNG NAM
A2: Địa chỉ: Cụm CN VLXD Tân An, X. Tân An, H. Vĩnh Cửu, T. Đồng Nai | T2: Tháng | U2: 12
A3: Điện thoại: 0251 3684039 *** Email: gachmenphuongnam@gmail.com
A4: BÁO CÁO TỔNG HỢP KẾT QUẢ SẢN XUẤT THÁNG 08 NĂM 2025 CỦA 2 DÂY CHUYỀN
A5: I. Sản lượng - Chất lượng - Thu hồi Tổng A1+A+B/ép:
A6: DC | B6: Kích thước | C6: KH/TH | D6: ĐVT | E6: Tổng sản lượng ép | F6: Sản lượng thu hồi | I6: Tổng (A1+A+B) | J6: Số ngày SX | K6: TB/ ngày | L6: A/ép | M6: C/ép | N6: Huỷ/ép | O6: T/g dừng 2MF
F7: A1 | G7: A | H7: B | K7: m2 | L7: % | O7: Phút/ngày
B8: Kích thước | C8: KH/TH | D8: ĐVT | E8: Tổng sản lượng ép | F8: A1 | G8: A | H8: B | I8: Tổng (A1+A+B) | J8: Số ngày SX | K8: TB/ ngày | L8: A/ép | M8: C/ép | N8: Huỷ/ép | O8: T/g dừng 2MF
A9: DC1 | B9: 30x60 | C9: Kế hoạch | D9: m2 | E9: =SUMIFS( INDEX('Data tổng hợp I'!$G$2:$Q$1858,0,MATCH(E$8,'Data tổng hợp I'!$G$2:$Q$2,0)), 'Data tổng hợp I'!$B$2:$B$1858,'Form mẫu'!$U$2, 'Data tổng hợp I'!$C$2:$C$1858,'Form mẫu'!$A9, 'Data tổng hợp I'!$D$2:$D$1858,'Form mẫu'!$B9, 'Data tổng hợp I'!$E$2:$E$1858,'Form mẫu'!$C9, 'Data tổng hợp I'!$F$2:$F$1858,'Form mẫu'!$D9 ) -> 0 | F9: =SUMIFS( INDEX('Data tổng hợp I'!$G$2:$Q$1858,0,MATCH(F$8,'Data tổng hợp I'!$G$2:$Q$2,0)), 'Data tổng hợp I'!$B$2:$B$1858,'Form mẫu'!$U$2, 'Data tổng hợp I'!$C$2:$C$1858,'Form mẫu'!$A9, 'Data tổng hợp I'!$D$2:$D$1858,'Form mẫu'!$B9, 'Data tổng hợp I'!$E$2:$E$1858,'Form mẫu'!$C9, 'Data tổng hợp I'!$F$2:$F$1858,'Form mẫu'!$D9 ) -> 0 | G9: =SUMIFS( INDEX('Data tổng hợp I'!$G$2:$Q$1858,0,MATCH(G$8,'Data tổng hợp I'!$G$2:$Q$2,0)), 'Data tổng hợp I'!$B$2:$B$1858,'Form mẫu'!$U$2, 'Data tổng hợp I'!$C$2:$C$1858,'Form mẫu'!$A9, 'Data tổng hợp I'!$D$2:$D$1858,'Form mẫu'!$B9, 'Data tổng hợp I'!$E$2:$E$1858,'Form mẫu'!$C9, 'Data tổng hợp I'!$F$2:$F$1858,'Form mẫu'!$D9 ) -> 0 | H9: =SUMIFS( INDEX('Data tổng hợp I'!$G$2:$Q$1858,0,MATCH(H$8,'Data tổng hợp I'!$G$2:$Q$2,0)), 'Data tổng hợp I'!$B$2:$B$1858,'Form mẫu'!$U$2, 'Data tổng hợp I'!$C$2:$C$1858,'Form mẫu'!$A9, 'Data tổng hợp I'!$D$2:$D$1858,'Form mẫu'!$B9, 'Data tổng hợp I'!$E$2:$E$1858,'Form mẫu'!$C9, 'Data tổng hợp I'!$F$2:$F$1858,'Form mẫu'!$D9 ) -> 0 | I9: =SUMIFS( INDEX('Data tổng hợp I'!$G$2:$Q$1858,0,MATCH(I$8,'Data tổng hợp I'!$G$2:$Q$2,0)), 'Data tổng hợp I'!$B$2:$B$1858,'Form mẫu'!$U$2, 'Data tổng hợp I'!$C$2:$C$1858,'Form mẫu'!$A9, 'Data tổng hợp I'!$D$2:$D$1858,'Form mẫu'!$B9, 'Data tổng hợp I'!$E$2:$E$1858,'Form mẫu'!$C9, 'Data tổng hợp I'!$F$2:$F$1858,'Form mẫu'!$D9 ) -> 0 | J9: =SUMIFS( INDEX('Data tổng hợp I'!$G$2:$Q$1858,0,MATCH(J$8,'Data tổng hợp I'!$G$2:$Q$2,0)), 'Data tổng hợp I'!$B$2:$B$1858,'Form mẫu'!$U$2, 'Data tổng hợp I'!$C$2:$C$1858,'Form mẫu'!$A9, 'Data tổng hợp I'!$D$2:$D$1858,'Form mẫu'!$B9, 'Data tổng hợp I'!$E$2:$E$1858,'Form mẫu'!$C9, 'Data tổng hợp I'!$F$2:$F$1858,'Form mẫu'!$D9 ) -> 0 | K9: =SUMIFS( INDEX('Data tổng hợp I'!$G$2:$Q$1858,0,MATCH(K$8,'Data tổng hợp I'!$G$2:$Q$2,0)), 'Data tổng hợp I'!$B$2:$B$1858,'Form mẫu'!$U$2, 'Data tổng hợp I'!$C$2:$C$1858,'Form mẫu'!$A9, 'Data tổng hợp I'!$D$2:$D$1858,'Form mẫu'!$B9, 'Data tổng hợp I'!$E$2:$E$1858,'Form mẫu'!$C9, 'Data tổng hợp I'!$F$2:$F$1858,'Form mẫu'!$D9 ) -> 0 | L9: =SUMIFS( INDEX('Data tổng hợp I'!$G$2:$Q$1858,0,MATCH(L$8,'Data tổng hợp I'!$G$2:$Q$2,0)), 'Data tổng hợp I'!$B$2:$B$1858,'Form mẫu'!$U$2, 'Data tổng hợp I'!$C$2:$C$1858,'Form mẫu'!$A9, 'Data tổng hợp I'!$D$2:$D$1858,'Form mẫu'!$B9, 'Data tổng hợp I'!$E$2:$E$1858,'Form mẫu'!$C9, 'Data tổng hợp I'!$F$2:$F$1858,'Form mẫu'!$D9 ) -> 0 | ... O9: =SUMIFS( INDEX('Data tổng hợp I'!$G$2:$Q$1858,0,MATCH(O$8,'Data tổng hợp I'!$G$2:$Q$2,0)), 'Data tổng hợp I'!$B$2:$B$1858,'Form mẫu'!$U$2, 'Data tổng hợp I'!$C$2:$C$1858,'Form mẫu'!$A9, 'Data tổng hợp I'!$D$2:$D$1858,'Form mẫu'!$B9, 'Data tổng hợp I'!$E$2:$E$1858,'Form mẫu'!$C9, 'Data tổng hợp I'!$F$2:$F$1858,'Form mẫu'!$D9 ) -> 0
A10: DC1 | B10: 30x60 | C10: Kế hoạch | D10: % | E10: =SUMIFS( INDEX('Data tổng hợp I'!$G$2:$Q$1858,0,MATCH(E$8,'Data tổng hợp I'!$G$2:$Q$2,0)), 'Data tổng hợp I'!$B$2:$B$1858,'Form mẫu'!$U$2, 'Data tổng hợp I'!$C$2:$C$1858,'Form mẫu'!$A10, 'Data tổng hợp I'!$D$2:$D$1858,'Form mẫu'!$B10, 'Data tổng hợp I'!$E$2:$E$1858,'Form mẫu'!$C10, 'Data tổng hợp I'!$F$2:$F$1858,'Form mẫu'!$D10 ) -> 0 | F10: =SUMIFS( INDEX('Data tổng hợp I'!$G$2:$Q$1858,0,MATCH(F$8,'Data tổng hợp I'!$G$2:$Q$2,0)), 'Data tổng hợp I'!$B$2:$B$1858,'Form mẫu'!$U$2, 'Data tổng hợp I'!$C$2:$C$1858,'Form mẫu'!$A10, 'Data tổng hợp I'!$D$2:$D$1858,'Form mẫu'!$B10, 'Data tổng hợp I'!$E$2:$E$1858,'Form mẫu'!$C10, 'Data tổng hợp I'!$F$2:$F$1858,'Form mẫu'!$D10 ) -> 0 | G10: =SUMIFS( INDEX('Data tổng hợp I'!$G$2:$Q$1858,0,MATCH(G$8,'Data tổng hợp I'!$G$2:$Q$2,0)), 'Data tổng hợp I'!$B$2:$B$1858,'Form mẫu'!$U$2, 'Data tổng hợp I'!$C$2:$C$1858,'Form mẫu'!$A10, 'Data tổng hợp I'!$D$2:$D$1858,'Form mẫu'!$B10, 'Data tổng hợp I'!$E$2:$E$1858,'Form mẫu'!$C10, 'Data tổng hợp I'!$F$2:$F$1858,'Form mẫu'!$D10 ) -> 0 | H10: =SUMIFS( INDEX('Data tổng hợp I'!$G$2:$Q$1858,0,MATCH(H$8,'Data tổng hợp I'!$G$2:$Q$2,0)), 'Data tổng hợp I'!$B$2:$B$1858,'Form mẫu'!$U$2, 'Data tổng hợp I'!$C$2:$C$1858,'Form mẫu'!$A10, 'Data tổng hợp I'!$D$2:$D$1858,'Form mẫu'!$B10, 'Data tổng hợp I'!$E$2:$E$1858,'Form mẫu'!$C10, 'Data tổng hợp I'!$F$2:$F$1858,'Form mẫu'!$D10 ) -> 0 | I10: =SUMIFS( INDEX('Data tổng hợp I'!$G$2:$Q$1858,0,MATCH(I$8,'Data tổng hợp I'!$G$2:$Q$2,0)), 'Data tổng hợp I'!$B$2:$B$1858,'Form mẫu'!$U$2, 'Data tổng hợp I'!$C$2:$C$1858,'Form mẫu'!$A10, 'Data tổng hợp I'!$D$2:$D$1858,'Form mẫu'!$B10, 'Data tổng hợp I'!$E$2:$E$1858,'Form mẫu'!$C10, 'Data tổng hợp I'!$F$2:$F$1858,'Form mẫu'!$D10 ) -> 0 | J10: =SUMIFS( INDEX('Data tổng hợp I'!$G$2:$Q$1858,0,MATCH(J$8,'Data tổng hợp I'!$G$2:$Q$2,0)), 'Data tổng hợp I'!$B$2:$B$1858,'Form mẫu'!$U$2, 'Data tổng hợp I'!$C$2:$C$1858,'Form mẫu'!$A10, 'Data tổng hợp I'!$D$2:$D$1858,'Form mẫu'!$B10, 'Data tổng hợp I'!$E$2:$E$1858,'Form mẫu'!$C10, 'Data tổng hợp I'!$F$2:$F$1858,'Form mẫu'!$D10 ) -> 0 | K10: =SUMIFS( INDEX('Data tổng hợp I'!$G$2:$Q$1858,0,MATCH(K$8,'Data tổng hợp I'!$G$2:$Q$2,0)), 'Data tổng hợp I'!$B$2:$B$1858,'Form mẫu'!$U$2, 'Data tổng hợp I'!$C$2:$C$1858,'Form mẫu'!$A10, 'Data tổng hợp I'!$D$2:$D$1858,'Form mẫu'!$B10, 'Data tổng hợp I'!$E$2:$E$1858,'Form mẫu'!$C10, 'Data tổng hợp I'!$F$2:$F$1858,'Form mẫu'!$D10 ) -> 0 | L10: =SUMIFS( INDEX('Data tổng hợp I'!$G$2:$Q$1858,0,MATCH(L$8,'Data tổng hợp I'!$G$2:$Q$2,0)), 'Data tổng hợp I'!$B$2:$B$1858,'Form mẫu'!$U$2, 'Data tổng hợp I'!$C$2:$C$1858,'Form mẫu'!$A10, 'Data tổng hợp I'!$D$2:$D$1858,'Form mẫu'!$B10, 'Data tổng hợp I'!$E$2:$E$1858,'Form mẫu'!$C10, 'Data tổng hợp I'!$F$2:$F$1858,'Form mẫu'!$D10 ) -> 0 | ... O10: =SUMIFS( INDEX('Data tổng hợp I'!$G$2:$Q$1858,0,MATCH(O$8,'Data tổng hợp I'!$G$2:$Q$2,0)), 'Data tổng hợp I'!$B$2:$B$1858,'Form mẫu'!$U$2, 'Data tổng hợp I'!$C$2:$C$1858,'Form mẫu'!$A10, 'Data tổng hợp I'!$D$2:$D$1858,'Form mẫu'!$B10, 'Data tổng hợp I'!$E$2:$E$1858,'Form mẫu'!$C10, 'Data tổng hợp I'!$F$2:$F$1858,'Form mẫu'!$D10 ) -> 0
